Workbook

Sheet PARÁMETROS
A1: PARÁMETROS DEL CÁLCULO Y PRECIOS UNITARIOS (CUSCO)
A2: Celdas AMARILLAS con texto azul = datos editables. Todo el libro se recalcula al cambiarlas.
A4: 1. DATOS GENERALES
A5: Parámetro | B5: Valor | C5: Unidad | D5: Fuente / observación
A6: Fecha de inicio de obra (casco) | B6: 46300 | C6: fecha | D6: Dato de obra: editar
A7: Fecha de corte del avance | B7: 46300 | C7: fecha | D7: Actualizar cada semana (DASHBOARD)
A8: Desperdicio de concreto | B8: 0.05 | C8: % | D8: Dato del usuario (5 %)
A9: Desperdicio / rotura de casetones | B9: 0.03 | C9: % | D9: Supuesto: manipuleo de EPS
A10: N° de usos de la madera | B10: 4 | C10: usos | D10: Editable (práctica usual 3-5)
A11: N° de usos del triplay | B11: 5 | C11: usos | D11: Editable (triplay 18 mm)
A12: N° de usos de los puntales | B12: 8 | C12: usos | D12: Editable (eucalipto rollizo)
A13: Alambre N°16 por kg de acero | B13: 0.03 | C13: kg/kg | D13: APU 'Acero corrugado fy=4200' (CAPECO): 0.030 kg/kg
A14: Dados por zapata | B14: 9 | C14: und/zapata | D14: Supuesto: malla 3x3
A15: Cortes por disco de 7" | B15: 150 | C15: cortes | D15: Estimado; 1 corte por pieza
A16: Consumo de curador químico | B16: 0.2 | C16: L/m² | D16: Rendimiento típico de membranas de curado (≈5 m²/L)
A17: Consumo de desmoldante | B17: 0.08 | C17: L/m² | D17: Estimado (≈1 gal por 50 m²)
... A22: Traslape Ø3/4" (barras > 9 m) | B22: 1.15 | C22: m | D22: Lámina E-10, nota 8 (sup. clase B). Informativo: el plan de corte ya lo usa
A24: 2. LOSA ALIGERADA (casetón de poliestireno EPS; el modelo trae losa maciza de 200 mm por criterio)
A25: Parámetro | B25: Valor | C25: Unidad | D25: Fuente / observación
A26: Altura total de losa | B26: 0.2 | C26: m | D26: Láminas E-04 a E-07
A27: Espesor de losita | B27: 0.05 | C27: m | D27: Láminas E-04 a E-07
A28: Ancho de vigueta | B28: 0.1 | C28: m | D28: Láminas E-04 a E-07
A29: Ancho del casetón | B29: 0.3 | C29: m | D29: Casetón EPS 1.20 x 0.30 x 0.15
A30: Alto del casetón | B30: 0.15 | C30: m | D30: Casetón EPS 1.20 x 0.30 x 0.15
A31: Largo del casetón | B31: 1.2 | C31: m | D31: Casetón EPS 1.20 x 0.30 x 0.15
A32: Concreto por m² de aligerado | B32: =PARÁMETROS!$B$27+PARÁMETROS!$B$28*PARÁMETROS!$B$30/(PARÁMETROS!$B$28+PARÁMETROS!$B$29) -> 0.0875 | C32: m³/m² | D32: losita + vigueta x alto casetón / separación de viguetas
A33: Casetones por m² de aligerado | B33: =1/((PARÁMETROS!$B$28+PARÁMETROS!$B$29)*PARÁMETROS!$B$31) -> 2.0833333 | C33: und/m² | D33: 1 / (separación de viguetas x largo del casetón)
A35: 3. f'c POR ELEMENTO (no existe en el modelo: dato de las especificaciones, láminas E-01 a E-10)
A36: Elemento | B36: f'c (kg/cm²) | D36: Fuente / observación
A37: Zapatas | B37: 210 | D37: Especificación del proyecto (nota E-10)
A38: Vigas de conexión | B38: 210 | D38: Especificación del proyecto (nota E-10)
A39: Cimiento de escalera | B39: 210 | D39: Especificación del proyecto (nota E-10)
A40: Columnas | B40: 210 | D40: Especificación del proyecto (nota E-10)
A41: Vigas | B41: 210 | D41: Especificación del proyecto (nota E-10)
A42: Losa aligerada | B42: 210 | D42: Especificación del proyecto (nota E-10)
A43: Escalera | B43: 210 | D43: Especificación del proyecto (nota E-10)
A44: Falso piso | B44: 175 | D44: Especificación del proyecto (nota E-10)
A45: Solado | B45: 100 | D45: Especificación del proyecto (nota E-10)
A47: 4. DOSIFICACIÓN POR m³ DE CONCRETO (cemento en bolsas de 42.5 kg, piedra chancada 1/2")
A48: f'c (kg/cm²) | B48: Cemento (bls/m³) | C48: Arena gruesa (m³/m³) | D48: Piedra chancada (m³/m³) | E48: Agua (L/m³) | F48: Fuente
...

Sheet METRADO POR NIVEL
A1: METRADO POR NIVEL - CASCO ESTRUCTURAL
A2: Cantidades del modelo IFC (hoja DATOS MODELO) + parámetros. Columnas I a W: insumos que genera cada partida.
A4: CIMENTACIÓN
A5: Nivel | B5: Partida | C5: Elemento | D5: Unidad | E5: Cantidad neta | F5: Desperdicio | G5: Cantidad total | H5: f'c / tipo | I5: Cemento (bls) | J5: Arena gruesa (m³) | K5: Piedra 1/2" (m³) | L5: Agua (m³) | M5: Casetón EPS (und) | N5: Alambre N°16 (kg) | O5: Madera tornillo (p²) | P5: Triplay (m²) | Q5: Clavos 3" (kg) | R5: Alambre N°8 (kg) | S5: Puntales (und) | T5: Desmoldante (gal) | U5: Curador (gal) | V5: Dados (und) | W5: Discos de corte (und) | X5: Nota
A6: CIMENTACIÓN | B6: Concreto | C6: Zapatas | D6: m³ | E6: =SUMIFS('DATOS MODELO'!$F$5:$F$227,'DATOS MODELO'!$B$5:$B$227,"CIMENTACIÓN",'DATOS MODELO'!$C$5:$C$227,"Zapatas") -> 23.791993 | F6: =PARÁMETROS!$B$8 -> 0.05 | G6: =E6*(1+F6) -> 24.981593 | H6: =INDEX(PARÁMETROS!$B$37:$B$45,MATCH(C6,PARÁMETROS!$A$37:$A$45,0)) -> 210 | I6: =G6*INDEX(PARÁMETROS!$B$49:$B$54,MATCH(H6,PARÁMETROS!$A$49:$A$54,0)) -> 243.0709 | J6: =G6*INDEX(PARÁMETROS!$C$49:$C$54,MATCH(H6,PARÁMETROS!$A$49:$A$54,0)) -> 12.990428 | K6: =G6*INDEX(PARÁMETROS!$D$49:$D$54,MATCH(H6,PARÁMETROS!$A$49:$A$54,0)) -> 13.240244 | L6: =G6*INDEX(PARÁMETROS!$E$49:$E$54,MATCH(H6,PARÁMETROS!$A$49:$A$54,0))/1000 -> 4.6465763 | X6: Vaciadas contra el terreno
A7: CIMENTACIÓN | B7: Concreto | C7: Vigas de conexión | D7: m³ | E7: =SUMIFS('DATOS MODELO'!$F$5:$F$227,'DATOS MODELO'!$B$5:$B$227,"CIMENTACIÓN",'DATOS MODELO'!$C$5:$C$227,"Vigas de conexión") -> 5.3450015 | F7: =PARÁMETROS!$B$8 -> 0.05 | G7: =E7*(1+F7) -> 5.6122516 | H7: =INDEX(PARÁMETROS!$B$37:$B$45,MATCH(C7,PARÁMETROS!$A$37:$A$45,0)) -> 210 | I7: =G7*INDEX(PARÁMETROS!$B$49:$B$54,MATCH(H7,PARÁMETROS!$A$49:$A$54,0)) -> 54.607208 | J7: =G7*INDEX(PARÁMETROS!$C$49:$C$54,MATCH(H7,PARÁMETROS!$A$49:$A$54,0)) -> 2.9183708 | K7: =G7*INDEX(PARÁMETROS!$D$49:$D$54,MATCH(H7,PARÁMETROS!$A$49:$A$54,0)) -> 2.9744933 | L7: =G7*INDEX(PARÁMETROS!$E$49:$E$54,MATCH(H7,PARÁMETROS!$A$49:$A$54,0))/1000 -> 1.0438788
A8: CIMENTACIÓN | B8: Concreto | C8: Cimiento de escalera | D8: m³ | E8: =SUMIFS('DATOS MODELO'!$F$5:$F$227,'DATOS MODELO'!$B$5:$B$227,"CIMENTACIÓN",'DATOS MODELO'!$C$5:$C$227,"Cimiento de escalera") -> 0.62499998 | F8: =PARÁMETROS!$B$8 -> 0.05 | G8: =E8*(1+F8) -> 0.65624998 | H8: =INDEX(PARÁMETROS!$B$37:$B$45,MATCH(C8,PARÁMETROS!$A$37:$A$45,0)) -> 210 | I8: =G8*INDEX(PARÁMETROS!$B$49:$B$54,MATCH(H8,PARÁMETROS!$A$49:$A$54,0)) -> 6.3853123 | J8: =G8*INDEX(PARÁMETROS!$C$49:$C$54,MATCH(H8,PARÁMETROS!$A$49:$A$54,0)) -> 0.34124999 | K8: =G8*INDEX(PARÁMETROS!$D$49:$D$54,MATCH(H8,PARÁMETROS!$A$49:$A$54,0)) -> 0.34781249 | L8: =G8*INDEX(PARÁMETROS!$E$49:$E$54,MATCH(H8,PARÁMETROS!$A$49:$A$54,0))/1000 -> 0.1220625
A9: CIMENTACIÓN | B9: Concreto | C9: Solado | D9: m³ | E9: =('DATOS MODELO'!$B$283+'DATOS MODELO'!$B$284)*PARÁMETROS!$B$19*PARÁMETROS!$B$18 -> 5.7507 | F9: =PARÁMETROS!$B$8 -> 0.05 | G9: =E9*(1+F9) -> 6.038235 | H9: =INDEX(PARÁMETROS!$B$37:$B$45,MATCH(C9,PARÁMETROS!$A$37:$A$45,0)) -> 100 | I9: =G9*INDEX(PARÁMETROS!$B$49:$B$54,MATCH(H9,PARÁMETROS!$A$49:$A$54,0)) -> 31.398822 | J9: =G9*INDEX(PARÁMETROS!$C$49:$C$54,MATCH(H9,PARÁMETROS!$A$49:$A$54,0)) -> 3.3814116 | K9: =G9*INDEX(PARÁMETROS!$D$49:$D$54,MATCH(H9,PARÁMETROS!$A$49:$A$54,0)) -> 4.1059998 | L9: =G9*INDEX(PARÁMETROS!$E$49:$E$54,MATCH(H9,PARÁMETROS!$A$49:$A$54,0))/1000 -> 1.0989588 | X9: Partida evitable (no modelada): área bajo zapatas y VC x espesor
A10: CIMENTACIÓN | B10: Encofrado | C10: Vigas de conexión | D10: m² | E10: =SUMIFS('DATOS MODELO'!$G$5:$G$227,'DATOS MODELO'!$B$5:$B$227,"CIMENTACIÓN",'DATOS MODELO'!$C$5:$C$227,"Vigas de conexión") -> 40.060636 | F10: 0 | G10: =E10*(1+F10) -> 40.060636 | H10: VC costados | O10: =G10*INDEX(PARÁMETROS!$B$58:$B$66,MATCH(H10,PARÁMETROS!$A$58:$A$66,0))/PARÁMETROS!$B$10 -> 35.053057 | P10: =G10*INDEX(PARÁMETROS!$C$58:$C$66,MATCH(H10,PARÁMETROS!$A$58:$A$66,0))/PARÁMETROS!$B$11 -> 0 | Q10: =G10*INDEX(PARÁMETROS!$D$58:$D$66,MATCH(H10,PARÁMETROS!$A$58:$A$66,0)) -> 6.0090954 | R10: =G10*INDEX(PARÁMETROS!$E$58:$E$66,MATCH(H10,PARÁMETROS!$A$58:$A$66,0)) -> 8.0121272 | S10: =G10*INDEX(PARÁMETROS!$F$58:$F$66,MATCH(H10,PARÁMETROS!$A$58:$A$66,0))/PARÁMETROS!$B$12 -> 0 | T10: =G10*PARÁMETROS!$B$17/3.785 -> 0.84672414 | V10: =G10*INDEX(PARÁMETROS!$G$58:$G$66,MATCH(H10,PARÁMETROS!$A$58:$A$66,0)) -> 80.121272 | X10: Fondo sobre solado/terreno
A11: CIMENTACIÓN | B11: Encofrado | C11: Cimiento de escalera | D11: m² | E11: =SUMIFS('DATOS MODELO'!$G$5:$G$227,'DATOS MODELO'!$B$5:$B$227,"CIMENTACIÓN",'DATOS MODELO'!$C$5:$C$227,"Cimiento de escalera") -> 2.9355468 | F11: 0 | G11: =E11*(1+F11) -> 2.9355468 | H11: Cimiento escalera | O11: =G11*INDEX(PARÁMETROS!$B$58:$B$66,MATCH(H11,PARÁMETROS!$A$58:$A$66,0))/PARÁMETROS!$B$10 -> 2.5686034 | P11: =G11*INDEX(PARÁMETROS!$C$58:$C$66,MATCH(H11,PARÁMETROS!$A$58:$A$66,0))/PARÁMETROS!$B$11 -> 0 | Q11: =G11*INDEX(PARÁMETROS!$D$58:$D$66,MATCH(H11,PARÁMETROS!$A$58:$A$66,0)) -> 0.44033202 | R11: =G11*INDEX(PARÁMETROS!$E$58:$E$66,MATCH(H11,PARÁMETROS!$A$58:$A$66,0)) -> 0.58710936 | S11: =G11*INDEX(PARÁMETROS!$F$58:$F$66,MATCH(H11,PARÁMETROS!$A$58:$A$66,0))/PARÁMETROS!$B$12 -> 0 | T11: =G11*PARÁMETROS!$B$17/3.785 -> 0.062045903 | V11: =G11*INDEX(PARÁMETROS!$G$58:$G$66,MATCH(H11,PARÁMETROS!$A$58:$A$66,0)) -> 5.8710936
A12: CIMENTACIÓN | B12: Acero | C12: Zapatas | D12: kg | E12: =SUMIFS('DATOS MODELO'!$E$232:$E$279,'DATOS MODELO'!$A$232:$A$279,"CIMENTACIÓN",'DATOS MODELO'!$B$232:$B$279,"Zapatas",'DATOS MODELO'!$C$232:$C$279,"1/4")*INDEX(PARÁMETROS!$B$93:$B$97,MATCH("1/4",PARÁMETROS!$A$93:$A$97,0))+SUMIFS('DATOS MODELO'!$E$232:$E$279,'DATOS MODELO'!$A$232:$A$279,"CIMENTACIÓN",'DATOS MODELO'!$B$232:$B$279,"Zapatas",'DATOS MODELO'!$C$232:$C$279,"3/8")*INDEX(PARÁMETROS!$B$93:$B$97,MATCH("3/8",PARÁMETROS!$A$93:$A$97,0))+SUMIFS('DATOS MODELO'!$E$232:$E$279,'DATOS MODELO'!$A$232:$A$279,"CIMENTACIÓN",'DATOS MODELO'!$B$232:$B$279,"Zapatas",'DATOS MODELO'!$C$232:$C$279,"1/2")*INDEX(PARÁMETROS!$B$93:$B$97,MATCH("1/2",PARÁMETROS!$A$93:$A$97,0))+SUMIFS('DATOS MODELO'!$E$232:$E$279,'DATOS MODELO'!$A$232:$A$279,"CIMENTACIÓN",'DATOS MODELO'!$B$232:$B$279,"Zapatas",'DATOS MODELO'!$C$232:$C$279,"5/8")*INDEX(PARÁMETROS!$B$93:$B$97,MATCH("5/8",PARÁMETROS!$A$93:$A$97,0))+SUMIFS('DATOS MODELO'!$E$232:$E$279,'DATOS MODELO'!$A$232:$A$279,"CIMENTACIÓN",'DATOS MODELO'!$B$232:$B$279,"Zapatas",'DATOS MODELO'!$C$232:$C$279,"3/4")*INDEX(PARÁMETROS!$B$93:$B$97,MATCH("3/4",PARÁMETROS!$A$93:$A$97,0)) -> 851.99289 | F12: 0 | G12: =E12*(1+F12) -> 851.99289 | H12: fy 4200 | N12: =G12*PARÁMETROS!$B$13 -> 25.559787 | V12: =COUNTIFS('DATOS MODELO'!$B$5:$B$227,"CIMENTACIÓN",'DATOS MODELO'!$C$5:$C$227,"Zapatas")*PARÁMETROS!$B$14 -> 126 | W12: =SUMIFS('DATOS MODELO'!$D$232:$D$279,'DATOS MODELO'!$A$232:$A$279,"CIMENTACIÓN",'DATOS MODELO'!$B$232:$B$279,"Zapatas")/PARÁMETROS!$B$15 -> 1.84 | X12: Desperdicio de corte: ver ACERO – DESPIECE (varillas de 9 m)
A13: CIMENTACIÓN | B13: Acero | C13: Vigas de conexión | D13: kg | E13: =SUMIFS('DATOS MODELO'!$E$232:$E$279,'DATOS MODELO'!$A$232:$A$279,"CIMENTACIÓN",'DATOS MODELO'!$B$232:$B$279,"Vigas de conexión",'DATOS MODELO'!$C$232:$C$279,"1/4")*INDEX(PARÁMETROS!$B$93:$B$97,MATCH("1/4",PARÁMETROS!$A$93:$A$97,0))+SUMIFS('DATOS MODELO'!$E$232:$E$279,'DATOS MODELO'!$A$232:$A$279,"CIMENTACIÓN",'DATOS MODELO'!$B$232:$B$279,"Vigas de conexión",'DATOS MODELO'!$C$232:$C$279,"3/8")*INDEX(PARÁMETROS!$B$93:$B$97,MATCH("3/8",PARÁMETROS!$A$93:$A$97,0))+SUMIFS('DATOS MODELO'!$E$232:$E$279,'DATOS MODELO'!$A$232:$A$279,"CIMENTACIÓN",'DATOS MODELO'!$B$232:$B$279,"Vigas de conexión",'DATOS MODELO'!$C$232:$C$279,"1/2")*INDEX(PARÁMETROS!$B$93:$B$97,MATCH("1/2",PARÁMETROS!$A$93:$A$97,0))+SUMIFS('DATOS MODELO'!$E$232:$E$279,'DATOS MODELO'!$A$232:$A$279,"CIMENTACIÓN",'DATOS MODELO'!$B$232:$B$279,"Vigas de conexión",'DATOS MODELO'!$C$232:$C$279,"5/8")*INDEX(PARÁMETROS!$B$93:$B$97,MATCH("5/8",PARÁMETROS!$A$93:$A$97,0))+SUMIFS('DATOS MODELO'!$E$232:$E$279,'DATOS MODELO'!$A$232:$A$279,"CIMENTACIÓN",'DATOS MODELO'!$B$232:$B$279,"Vigas de conexión",'DATOS MODELO'!$C$232:$C$279,"3/4")*INDEX(PARÁMETROS!$B$93:$B$97,MATCH("3/4",PARÁMETROS!$A$93:$A$97,0)) -> 1534.9779 | F13: 0 | G13: =E13*(1+F13) -> 1534.9779 | H13: fy 4200 | N13: =G13*PARÁMETROS!$B$13 -> 46.049337 | W13: =SUMIFS('DATOS MODELO'!$D$232:$D$279,'DATOS MODELO'!$A$232:$A$279,"CIMENTACIÓN",'DATOS MODELO'!$B$232:$B$279,"Vigas de conexión")/PARÁMETROS!$B$15 -> 3.1466667 | X13: Desperdicio de corte: ver ACERO – DESPIECE (varillas de 9 m)
A14: CIMENTACIÓN | B14: Acero | C14: Cimiento de escalera | D14: kg | E14: =SUMIFS('DATOS MODELO'!$E$232:$E$279,'DATOS MODELO'!$A$232:$A$279,"CIMENTACIÓN",'DATOS MODELO'!$B$232:$B$279,"Cimiento de escalera",'DATOS MODELO'!$C$232:$C$279,"1/4")*INDEX(PARÁMETROS!$B$93:$B$97,MATCH("1/4",PARÁMETROS!$A$93:$A$97,0))+SUMIFS('DATOS MODELO'!$E$232:$E$279,'DATOS MODELO'!$A$232:$A$279,"CIMENTACIÓN",'DATOS MODELO'!$B$232:$B$279,"Cimiento de escalera",'DATOS MODELO'!$C$232:$C$279,"3/8")*INDEX(PARÁMETROS!$B$93:$B$97,MATCH("3/8",PARÁMETROS!$A$93:$A$97,0))+SUMIFS('DATOS MODELO'!$E$232:$E$279,'DATOS MODELO'!$A$232:$A$279,"CIMENTACIÓN",'DATOS MODELO'!$B$232:$B$279,"Cimiento de escalera",'DATOS MODELO'!$C$232:$C$279,"1/2")*INDEX(PARÁMETROS!$B$93:$B$97,MATCH("1/2",PARÁMETROS!$A$93:$A$97,0))+SUMIFS('DATOS MODELO'!$E$232:$E$279,'DATOS MODELO'!$A$232:$A$279,"CIMENTACIÓN",'DATOS MODELO'!$B$232:$B$279,"Cimiento de escalera",'DATOS MODELO'!$C$232:$C$279,"5/8")*INDEX(PARÁMETROS!$B$93:$B$97,MATCH("5/8",PARÁMETROS!$A$93:$A$97,0))+SUMIFS('DATOS MODELO'!$E$232:$E$279,'DATOS MODELO'!$A$232:$A$279,"CIMENTACIÓN",'DATOS MODELO'!$B$232:$B$279,"Cimiento de escalera",'DATOS MODELO'!$C$232:$C$279,"3/4")*INDEX(PARÁMETROS!$B$93:$B$97,MATCH("3/4",PARÁMETROS!$A$93:$A$97,0)) -> 3.6568 | F14: 0 | G14: =E14*(1+F14) -> 3.6568 | H14: fy 4200 | N14: =G14*PARÁMETROS!$B$13 -> 0.109704 | W14: =SUMIFS('DATOS MODELO'!$D$232:$D$279,'DATOS MODELO'!$A$232:$A$279,"CIMENTACIÓN",'DATOS MODELO'!$B$232:$B$279,"Cimiento de escalera")/PARÁMETROS!$B$15 -> 0.033333333 | X14: Desperdicio de corte: ver ACERO – DESPIECE (varillas de 9 m)
A15: CIMENTACIÓN | B15: Curado | C15: Zapatas | D15: m² | E15: =SUMIFS('DATOS MODELO'!$I$5:$I$227,'DATOS MODELO'!$B$5:$B$227,"CIMENTACIÓN",'DATOS MODELO'!$C$5:$C$227,"Zapatas") -> 32.82054 | F15: 0 | G15: =E15*(1+F15) -> 32.82054 | H15: curador | U15: =G15*PARÁMETROS!$B$16/3.785 -> 1.7342426 | X15: Cara superior (costados contra terreno)
A16: CIMENTACIÓN | B16: Curado | C16: Vigas de conexión | D16: m² | E16: =SUMIFS('DATOS MODELO'!$I$5:$I$227,'DATOS MODELO'!$B$5:$B$227,"CIMENTACIÓN",'DATOS MODELO'!$C$5:$C$227,"Vigas de conexión")+SUMIFS('DATOS MODELO'!$J$5:$J$227,'DATOS MODELO'!$B$5:$B$227,"CIMENTACIÓN",'DATOS MODELO'!$C$5:$C$227,"Vigas de conexión") -> 52.585246 | F16: 0 | G16: =E16*(1+F16) -> 52.585246 | H16: curador | U16: =G16*PARÁMETROS!$B$16/3.785 -> 2.7786127
A17: CIMENTACIÓN | B17: Curado | C17: Cimiento de escalera | D17: m² | E17: =SUMIFS('DATOS MODELO'!$I$5:$I$227,'DATOS MODELO'!$B$5:$B$227,"CIMENTACIÓN",'DATOS MODELO'!$C$5:$C$227,"Cimiento de escalera")+SUMIFS('DATOS MODELO'!$J$5:$J$227,'DATOS MODELO'!$B$5:$B$227,"CIMENTACIÓN",'DATOS MODELO'!$C$5:$C$227,"Cimiento de escalera") -> 3.2486571 | F17: 0 | G17: =E17*(1+F17) -> 3.2486571 | H17: curador | U17: =G17*PARÁMETROS!$B$16/3.785 -> 0.17165956
A18: TOTAL CIMENTACIÓN | I18: =SUM(I6:I17) -> 335.46224 | J18: =SUM(J6:J17) -> 19.631461 | K18: =SUM(K6:K17) -> 20.66855 | L18: =SUM(L6:L17) -> 6.9114764 | M18: =SUM(M6:M17) -> 0 | N18: =SUM(N6:N17) -> 71.718828 | O18: =SUM(O6:O17) -> 37.62166 | P18: =SUM(P6:P17) -> 0 | ... W18: =SUM(W6:W17) -> 5.02
B19: Subtotal Concreto | D19: m³ | G19: =SUMIFS(G6:G17,B6:B17,"Concreto") -> 37.28833
B20: Subtotal Encofrado | D20: m² | G20: =SUMIFS(G6:G17,B6:B17,"Encofrado") -> 42.996183
B21: Subtotal Acero | D21: kg | G21: =SUMIFS(G6:G17,B6:B17,"Acero") -> 2390.6276
B22: Subtotal Curado | D22: m² | G22: =SUMIFS(G6:G17,B6:B17,"Curado") -> 88.654444
A24: NIVEL 1
A25: Nivel | B25: Partida | C25: Elemento | D25: Unidad | E25: Cantidad neta | F25: Desperdicio | G25: Cantidad total | H25: f'c / tipo | I25: Cemento (bls) | J25: Arena gruesa (m³) | K25: Piedra 1/2" (m³) | L25: Agua (m³) | M25: Casetón EPS (und) | N25: Alambre N°16 (kg) | O25: Madera tornillo (p²) | P25: Triplay (m²) | Q25: Clavos 3" (kg) | R25: Alambre N°8 (kg) | S25: Puntales (und) | T25: Desmoldante (gal) | U25: Curador (gal) | V25: Dados (und) | W25: Discos de corte (und) | X25: Nota
A26: NIVEL 1 | B26: Concreto | C26: Columnas | D26: m³ | E26: =SUMIFS('DATOS MODELO'!$F$5:$F$227,'DATOS MODELO'!$B$5:$B$227,"NIVEL 1",'DATOS MODELO'!$C$5:$C$227,"Columnas") -> 4.1939951 | F26: =PARÁMETROS!$B$8 -> 0.05 | G26: =E26*(1+F26) -> 4.4036949 | H26: =INDEX(PARÁMETROS!$B$37:$B$45,MATCH(C26,PARÁMETROS!$A$37:$A$45,0)) -> 210 | I26: =G26*INDEX(PARÁMETROS!$B$49:$B$54,MATCH(H26,PARÁMETROS!$A$49:$A$54,0)) -> 42.847951 | J26: =G26*INDEX(PARÁMETROS!$C$49:$C$54,MATCH(H26,PARÁMETROS!$A$49:$A$54,0)) -> 2.2899213 | K26: =G26*INDEX(PARÁMETROS!$D$49:$D$54,MATCH(H26,PARÁMETROS!$A$49:$A$54,0)) -> 2.3339583 | L26: =G26*INDEX(PARÁMETROS!$E$49:$E$54,MATCH(H26,PARÁMETROS!$A$49:$A$54,0))/1000 -> 0.81908724 | X26: Columnas de cimentación a N1
A27: NIVEL 1 | B27: Concreto | C27: Falso piso | D27: m³ | E27: =SUMIFS('DATOS MODELO'!$F$5:$F$227,'DATOS MODELO'!$B$5:$B$227,"NIVEL 1",'DATOS MODELO'!$C$5:$C$227,"Falso piso") -> 9.0525745 | F27: =PARÁMETROS!$B$8 -> 0.05 | G27: =E27*(1+F27) -> 9.5052032 | H27: =INDEX(PARÁMETROS!$B$37:$B$45,MATCH(C27,PARÁMETROS!$A$37:$A$45,0)) -> 175 | I27: =G27*INDEX(PARÁMETROS!$B$49:$B$54,MATCH(H27,PARÁMETROS!$A$49:$A$54,0)) -> 80.128863 | J27: =G27*INDEX(PARÁMETROS!$C$49:$C$54,MATCH(H27,PARÁMETROS!$A$49:$A$54,0)) -> 5.1328097 | K27: =G27*INDEX(PARÁMETROS!$D$49:$D$54,MATCH(H27,PARÁMETROS!$A$49:$A$54,0)) -> 5.2278618 | L27: =G27*INDEX(PARÁMETROS!$E$49:$E$54,MATCH(H27,PARÁMETROS!$A$49:$A$54,0))/1000 -> 1.7584626 | X27: e = 0.10 (modelo)
A28: NIVEL 1 | B28: Encofrado | C28: Columnas | D28: m² | E28: =SUMIFS('DATOS MODELO'!$G$5:$G$227,'DATOS MODELO'!$B$5:$B$227,"NIVEL 1",'DATOS MODELO'!$C$5:$C$227,"Columnas") -> 34.692085 | F28: 0 | G28: =E28*(1+F28) -> 34.692085 | H28: Columnas | O28: =G28*INDEX(PARÁMETROS!$B$58:$B$66,MATCH(H28,PARÁMETROS!$A$58:$A$66,0))/PARÁMETROS!$B$10 -> 26.019063 | P28: =G28*INDEX(PARÁMETROS!$C$58:$C$66,MATCH(H28,PARÁMETROS!$A$58:$A$66,0))/PARÁMETROS!$B$11 -> 7.2853378 | Q28: =G28*INDEX(PARÁMETROS!$D$58:$D$66,MATCH(H28,PARÁMETROS!$A$58:$A$66,0)) -> 5.2038127 | R28: =G28*INDEX(PARÁMETROS!$E$58:$E$66,MATCH(H28,PARÁMETROS!$A$58:$A$66,0)) -> 8.6730212 | S28: =G28*INDEX(PARÁMETROS!$F$58:$F$66,MATCH(H28,PARÁMETROS!$A$58:$A$66,0))/PARÁMETROS!$B$12 -> 0 | T28: =G28*PARÁMETROS!$B$17/3.785 -> 0.7332541 | V28: =G28*INDEX(PARÁMETROS!$G$58:$G$66,MATCH(H28,PARÁMETROS!$A$58:$A$66,0)) -> 69.384169
A29: NIVEL 1 | B29: Acero | C29: Columnas | D29: kg | E29: =SUMIFS('DATOS MODELO'!$E$232:$E$279,'DATOS MODELO'!$A$232:$A$279,"NIVEL 1",'DATOS MODELO'!$B$232:$B$279,"Columnas",'DATOS MODELO'!$C$232:$C$279,"1/4")*INDEX(PARÁMETROS!$B$93:$B$97,MATCH("1/4",PARÁMETROS!$A$93:$A$97,0))+SUMIFS('DATOS MODELO'!$E$232:$E$279,'DATOS MODELO'!$A$232:$A$279,"NIVEL 1",'DATOS MODELO'!$B$232:$B$279,"Columnas",'DATOS MODELO'!$C$232:$C$279,"3/8")*INDEX(PARÁMETROS!$B$93:$B$97,MATCH("3/8",PARÁMETROS!$A$93:$A$97,0))+SUMIFS('DATOS MODELO'!$E$232:$E$279,'DATOS MODELO'!$A$232:$A$279,"NIVEL 1",'DATOS MODELO'!$B$232:$B$279,"Columnas",'DATOS MODELO'!$C$232:$C$279,"1/2")*INDEX(PARÁMETROS!$B$93:$B$97,MATCH("1/2",PARÁMETROS!$A$93:$A$97,0))+SUMIFS('DATOS MODELO'!$E$232:$E$279,'DATOS MODELO'!$A$232:$A$279,"NIVEL 1",'DATOS MODELO'!$B$232:$B$279,"Columnas",'DATOS MODELO'!$C$232:$C$279,"5/8")*INDEX(PARÁMETROS!$B$93:$B$97,MATCH("5/8",PARÁMETROS!$A$93:$A$97,0))+SUMIFS('DATOS MODELO'!$E$232:$E$279,'DATOS MODELO'!$A$232:$A$279,"NIVEL 1",'DATOS MODELO'!$B$232:$B$279,"Columnas",'DATOS MODELO'!$C$232:$C$279,"3/4")*INDEX(PARÁMETROS!$B$93:$B$97,MATCH("3/4",PARÁMETROS!$A$93:$A$97,0)) -> 1285.4986 | F29: 0 | G29: =E29*(1+F29) -> 1285.4986 | H29: fy 4200 | N29: =G29*PARÁMETROS!$B$13 -> 38.564959 | W29: =SUMIFS('DATOS MODELO'!$D$232:$D$279,'DATOS MODELO'!$A$232:$A$279,"NIVEL 1",'DATOS MODELO'!$B$232:$B$279,"Columnas")/PARÁMETROS!$B$15 -> 6.12 | X29: Desperdicio de corte: ver ACERO – DESPIECE (varillas de 9 m)
A30: NIVEL 1 | B30: Curado | C30: Columnas | D30: m² | E30: =SUMIFS('DATOS MODELO'!$J$5:$J$227,'DATOS MODELO'!$B$5:$B$227,"NIVEL 1",'DATOS MODELO'!$C$5:$C$227,"Columnas") -> 34.692085 | F30: 0 | G30: =E30*(1+F30) -> 34.692085 | H30: curador | U30: =G30*PARÁMETROS!$B$16/3.785 -> 1.8331353
A31: NIVEL 1 | B31: Curado | C31: Falso piso | D31: m² | E31: =SUMIFS('DATOS MODELO'!$I$5:$I$227,'DATOS MODELO'!$B$5:$B$227,"NIVEL 1",'DATOS MODELO'!$C$5:$C$227,"Falso piso") -> 87.320832 | F31: 0 | G31: =E31*(1+F31) -> 87.320832 | H31: curador | U31: =G31*PARÁMETROS!$B$16/3.785 -> 4.6140466
A32: TOTAL NIVEL 1 | I32: =SUM(I26:I31) -> 122.97681 | J32: =SUM(J26:J31) -> 7.422731 | K32: =SUM(K26:K31) -> 7.56182 | L32: =SUM(L26:L31) -> 2.5775498 | M32: =SUM(M26:M31) -> 0 | N32: =SUM(N26:N31) -> 38.564959 | O32: =SUM(O26:O31) -> 26.019063 | P32: =SUM(P26:P31) -> 7.2853378 | ... W32: =SUM(W26:W31) -> 6.12
B33: Subtotal Concreto | D33: m³ | G33: =SUMIFS(G26:G31,B26:B31,"Concreto") -> 13.908898
B34: Subtotal Encofrado | D34: m² | G34: =SUMIFS(G26:G31,B26:B31,"Encofrado") -> 34.692085
B35: Subtotal Acero | D35: kg | G35: =SUMIFS(G26:G31,B26:B31,"Acero") -> 1285.4986
B36: Subtotal Curado | D36: m² | G36: =SUMIFS(G26:G31,B26:B31,"Curado") -> 122.01292
A38: NIVEL 2
A39: Nivel | B39: Partida | C39: Elemento | D39: Unidad | E39: Cantidad neta | F39: Desperdicio | G39: Cantidad total | H39: f'c / tipo | I39: Cemento (bls) | J39: Arena gruesa (m³) | K39: Piedra 1/2" (m³) | L39: Agua (m³) | M39: Casetón EPS (und) | N39: Alambre N°16 (kg) | O39: Madera tornillo (p²) | P39: Triplay (m²) | Q39: Clavos 3" (kg) | R39: Alambre N°8 (kg) | S39: Puntales (und) | T39: Desmoldante (gal) | U39: Curador (gal) | V39: Dados (und) | W39: Discos de corte (und) | X39: Nota
A40: NIVEL 2 | B40: Concreto | C40: Columnas | D40: m³ | E40: =SUMIFS('DATOS MODELO'!$F$5:$F$227,'DATOS MODELO'!$B$5:$B$227,"NIVEL 2",'DATOS MODELO'!$C$5:$C$227,"Columnas") -> 8.9459893 | F40: =PARÁMETROS!$B$8 -> 0.05 | G40: =E40*(1+F40) -> 9.3932888 | H40: =INDEX(PARÁMETROS!$B$37:$B$45,MATCH(C40,PARÁMETROS!$A$37:$A$45,0)) -> 210 | I40: =G40*INDEX(PARÁMETROS!$B$49:$B$54,MATCH(H40,PARÁMETROS!$A$49:$A$54,0)) -> 91.3967 | J40: =G40*INDEX(PARÁMETROS!$C$49:$C$54,MATCH(H40,PARÁMETROS!$A$49:$A$54,0)) -> 4.8845102 | K40: =G40*INDEX(PARÁMETROS!$D$49:$D$54,MATCH(H40,PARÁMETROS!$A$49:$A$54,0)) -> 4.9784431 | L40: =G40*INDEX(PARÁMETROS!$E$49:$E$54,MATCH(H40,PARÁMETROS!$A$49:$A$54,0))/1000 -> 1.7471517
A41: NIVEL 2 | B41: Concreto | C41: Vigas | D41: m³ | E41: =SUMIFS('DATOS MODELO'!$F$5:$F$227,'DATOS MODELO'!$B$5:$B$227,"NIVEL 2",'DATOS MODELO'!$C$5:$C$227,"Vigas") -> 6.1853209 | F41: =PARÁMETROS!$B$8 -> 0.05 | G41: =E41*(1+F41) -> 6.494587 | H41: =INDEX(PARÁMETROS!$B$37:$B$45,MATCH(C41,PARÁMETROS!$A$37:$A$45,0)) -> 210 | I41: =G41*INDEX(PARÁMETROS!$B$49:$B$54,MATCH(H41,PARÁMETROS!$A$49:$A$54,0)) -> 63.192331 | J41: =G41*INDEX(PARÁMETROS!$C$49:$C$54,MATCH(H41,PARÁMETROS!$A$49:$A$54,0)) -> 3.3771852 | K41: =G41*INDEX(PARÁMETROS!$D$49:$D$54,MATCH(H41,PARÁMETROS!$A$49:$A$54,0)) -> 3.4421311 | L41: =G41*INDEX(PARÁMETROS!$E$49:$E$54,MATCH(H41,PARÁMETROS!$A$49:$A$54,0))/1000 -> 1.2079932 | X41: Peralte bajo la losa (modelo con uniones)
A42: NIVEL 2 | B42: Concreto | C42: Losa aligerada | D42: m³ | E42: =SUMIFS('DATOS MODELO'!$L$5:$L$227,'DATOS MODELO'!$B$5:$B$227,"NIVEL 2",'DATOS MODELO'!$C$5:$C$227,"Losa aligerada")*PARÁMETROS!$B$32+(SUMIFS('DATOS MODELO'!$K$5:$K$227,'DATOS MODELO'!$B$5:$B$227,"NIVEL 2",'DATOS MODELO'!$C$5:$C$227,"Losa aligerada")-SUMIFS('DATOS MODELO'!$L$5:$L$227,'DATOS MODELO'!$B$5:$B$227,"NIVEL 2",'DATOS MODELO'!$C$5:$C$227,"Losa aligerada"))*PARÁMETROS!$B$26 -> 10.65635 | F42: =PARÁMETROS!$B$8 -> 0.05 | G42: =E42*(1+F42) -> 11.189167 | H42: =INDEX(PARÁMETROS!$B$37:$B$45,MATCH(C42,PARÁMETROS!$A$37:$A$45,0)) -> 210 | I42: =G42*INDEX(PARÁMETROS!$B$49:$B$54,MATCH(H42,PARÁMETROS!$A$49:$A$54,0)) -> 108.8706 | J42: =G42*INDEX(PARÁMETROS!$C$49:$C$54,MATCH(H42,PARÁMETROS!$A$49:$A$54,0)) -> 5.8183671 | K42: =G42*INDEX(PARÁMETROS!$D$49:$D$54,MATCH(H42,PARÁMETROS!$A$49:$A$54,0)) -> 5.9302588 | L42: =G42*INDEX(PARÁMETROS!$E$49:$E$54,MATCH(H42,PARÁMETROS!$A$49:$A$54,0))/1000 -> 2.0811852 | X42: Aligerado x concreto/m² + zonas macizas (sobre vigas y columnas, vigas chatas) x h
A43: NIVEL 2 | B43: Concreto | C43: Escalera | D43: m³ | E43: =SUMIFS('DATOS MODELO'!$F$5:$F$227,'DATOS MODELO'!$B$5:$B$227,"NIVEL 2",'DATOS MODELO'!$C$5:$C$227,"Escalera") -> 2.4227145 | F43: =PARÁMETROS!$B$8 -> 0.05 | G43: =E43*(1+F43) -> 2.5438503 | H43: =INDEX(PARÁMETROS!$B$37:$B$45,MATCH(C43,PARÁMETROS!$A$37:$A$45,0)) -> 210 | I43: =G43*INDEX(PARÁMETROS!$B$49:$B$54,MATCH(H43,PARÁMETROS!$A$49:$A$54,0)) -> 24.751663 | J43: =G43*INDEX(PARÁMETROS!$C$49:$C$54,MATCH(H43,PARÁMETROS!$A$49:$A$54,0)) -> 1.3228021 | K43: =G43*INDEX(PARÁMETROS!$D$49:$D$54,MATCH(H43,PARÁMETROS!$A$49:$A$54,0)) -> 1.3482406 | L43: =G43*INDEX(PARÁMETROS!$E$49:$E$54,MATCH(H43,PARÁMETROS!$A$49:$A$54,0))/1000 -> 0.47315615 | X43: Tramo que llega a este nivel
...

Sheet ACERO – DESPIECE
A1: ACERO – DESPIECE POR DIÁMETRO Y NIVEL (varillas comerciales de 9 m)
A2: Piezas y longitudes del modelo; varillas y retazos del PLAN DE CORTE. Unidad de compra: VARILLA de 9 m.
A4: Nivel | B4: Ø | C4: N° barras (modelo) | D4: Longitud neta (m) | E4: kg netos | F4: Varillas de 9 m (und) | G4: Longitud comprada (m) | H4: Longitud cortada (m) | I4: Traslape adicional (m) | J4: Retazos (m) | K4: Retazos reutilizables ≥ 1 m (m) | L4: Desperdicio real (%) | M4: kg comprados (referencia)
A5: CIMENTACIÓN | B5: 1/4 | C5: =SUMIFS('DATOS MODELO'!$D$232:$D$279,'DATOS MODELO'!$A$232:$A$279,A5,'DATOS MODELO'!$C$232:$C$279,B5) -> 0 | D5: =SUMIFS('DATOS MODELO'!$E$232:$E$279,'DATOS MODELO'!$A$232:$A$279,A5,'DATOS MODELO'!$C$232:$C$279,B5) -> 0 | E5: =D5*INDEX(PARÁMETROS!$B$93:$B$97,MATCH(B5,PARÁMETROS!$A$93:$A$97,0)) -> 0 | F5: =COUNTIFS('PLAN DE CORTE'!$A$5:$A$2516,A5,'PLAN DE CORTE'!$B$5:$B$2516,B5) -> 0 | G5: =F5*9 -> 0 | H5: =SUMIFS('PLAN DE CORTE'!$F$5:$F$2516,'PLAN DE CORTE'!$A$5:$A$2516,A5,'PLAN DE CORTE'!$B$5:$B$2516,B5) -> 0 | I5: =H5-D5 -> 0 | J5: =G5-H5 -> 0 | K5: =SUMIFS('PLAN DE CORTE'!$H$5:$H$2516,'PLAN DE CORTE'!$A$5:$A$2516,A5,'PLAN DE CORTE'!$B$5:$B$2516,B5) -> 0 | L5: =IF(G5>0,J5/G5,0) -> 0 | M5: =G5*INDEX(PARÁMETROS!$B$93:$B$97,MATCH(B5,PARÁMETROS!$A$93:$A$97,0)) -> 0
A6: CIMENTACIÓN | B6: 3/8 | C6: =SUMIFS('DATOS MODELO'!$D$232:$D$279,'DATOS MODELO'!$A$232:$A$279,A6,'DATOS MODELO'!$C$232:$C$279,B6) -> 387 | D6: =SUMIFS('DATOS MODELO'!$E$232:$E$279,'DATOS MODELO'!$A$232:$A$279,A6,'DATOS MODELO'!$C$232:$C$279,B6) -> 433.874 | E6: =D6*INDEX(PARÁMETROS!$B$93:$B$97,MATCH(B6,PARÁMETROS!$A$93:$A$97,0)) -> 242.96944 | F6: =COUNTIFS('PLAN DE CORTE'!$A$5:$A$2516,A6,'PLAN DE CORTE'!$B$5:$B$2516,B6) -> 49 | G6: =F6*9 -> 441 | H6: =SUMIFS('PLAN DE CORTE'!$F$5:$F$2516,'PLAN DE CORTE'!$A$5:$A$2516,A6,'PLAN DE CORTE'!$B$5:$B$2516,B6) -> 433.87444 | I6: =H6-D6 -> 0.00044341097 | J6: =G6-H6 -> 7.1255566 | K6: =SUMIFS('PLAN DE CORTE'!$H$5:$H$2516,'PLAN DE CORTE'!$A$5:$A$2516,A6,'PLAN DE CORTE'!$B$5:$B$2516,B6) -> 4.5251899 | L6: =IF(G6>0,J6/G6,0) -> 0.016157725 | M6: =G6*INDEX(PARÁMETROS!$B$93:$B$97,MATCH(B6,PARÁMETROS!$A$93:$A$97,0)) -> 246.96
A7: CIMENTACIÓN | B7: 1/2 | C7: =SUMIFS('DATOS MODELO'!$D$232:$D$279,'DATOS MODELO'!$A$232:$A$279,A7,'DATOS MODELO'!$C$232:$C$279,B7) -> 32 | D7: =SUMIFS('DATOS MODELO'!$E$232:$E$279,'DATOS MODELO'!$A$232:$A$279,A7,'DATOS MODELO'!$C$232:$C$279,B7) -> 44.773 | E7: =D7*INDEX(PARÁMETROS!$B$93:$B$97,MATCH(B7,PARÁMETROS!$A$93:$A$97,0)) -> 44.504362 | F7: =COUNTIFS('PLAN DE CORTE'!$A$5:$A$2516,A7,'PLAN DE CORTE'!$B$5:$B$2516,B7) -> 6 | G7: =F7*9 -> 54 | H7: =SUMIFS('PLAN DE CORTE'!$F$5:$F$2516,'PLAN DE CORTE'!$A$5:$A$2516,A7,'PLAN DE CORTE'!$B$5:$B$2516,B7) -> 44.772601 | I7: =H7-D7 -> -0.00039860953 | J7: =G7-H7 -> 9.2273986 | K7: =SUMIFS('PLAN DE CORTE'!$H$5:$H$2516,'PLAN DE CORTE'!$A$5:$A$2516,A7,'PLAN DE CORTE'!$B$5:$B$2516,B7) -> 6.2017124 | L7: =IF(G7>0,J7/G7,0) -> 0.17087775 | M7: =G7*INDEX(PARÁMETROS!$B$93:$B$97,MATCH(B7,PARÁMETROS!$A$93:$A$97,0)) -> 53.676
A8: CIMENTACIÓN | B8: 5/8 | C8: =SUMIFS('DATOS MODELO'!$D$232:$D$279,'DATOS MODELO'!$A$232:$A$279,A8,'DATOS MODELO'!$C$232:$C$279,B8) -> 244 | D8: =SUMIFS('DATOS MODELO'!$E$232:$E$279,'DATOS MODELO'!$A$232:$A$279,A8,'DATOS MODELO'!$C$232:$C$279,B8) -> 520.289 | E8: =D8*INDEX(PARÁMETROS!$B$93:$B$97,MATCH(B8,PARÁMETROS!$A$93:$A$97,0)) -> 807.48853 | F8: =COUNTIFS('PLAN DE CORTE'!$A$5:$A$2516,A8,'PLAN DE CORTE'!$B$5:$B$2516,B8) -> 61 | G8: =F8*9 -> 549 | H8: =SUMIFS('PLAN DE CORTE'!$F$5:$F$2516,'PLAN DE CORTE'!$A$5:$A$2516,A8,'PLAN DE CORTE'!$B$5:$B$2516,B8) -> 520.28886 | I8: =H8-D8 -> -0.00014299712 | J8: =G8-H8 -> 28.711143 | K8: =SUMIFS('PLAN DE CORTE'!$H$5:$H$2516,'PLAN DE CORTE'!$A$5:$A$2516,A8,'PLAN DE CORTE'!$B$5:$B$2516,B8) -> 19.959934 | L8: =IF(G8>0,J8/G8,0) -> 0.052297164 | M8: =G8*INDEX(PARÁMETROS!$B$93:$B$97,MATCH(B8,PARÁMETROS!$A$93:$A$97,0)) -> 852.048
A9: CIMENTACIÓN | B9: 3/4 | C9: =SUMIFS('DATOS MODELO'!$D$232:$D$279,'DATOS MODELO'!$A$232:$A$279,A9,'DATOS MODELO'!$C$232:$C$279,B9) -> 90 | D9: =SUMIFS('DATOS MODELO'!$E$232:$E$279,'DATOS MODELO'!$A$232:$A$279,A9,'DATOS MODELO'!$C$232:$C$279,B9) -> 579.716 | E9: =D9*INDEX(PARÁMETROS!$B$93:$B$97,MATCH(B9,PARÁMETROS!$A$93:$A$97,0)) -> 1295.6653 | F9: =COUNTIFS('PLAN DE CORTE'!$A$5:$A$2516,A9,'PLAN DE CORTE'!$B$5:$B$2516,B9) -> 75 | G9: =F9*9 -> 675 | H9: =SUMIFS('PLAN DE CORTE'!$F$5:$F$2516,'PLAN DE CORTE'!$A$5:$A$2516,A9,'PLAN DE CORTE'!$B$5:$B$2516,B9) -> 586.61642 | I9: =H9-D9 -> 6.9004223 | J9: =G9-H9 -> 88.383578 | K9: =SUMIFS('PLAN DE CORTE'!$H$5:$H$2516,'PLAN DE CORTE'!$A$5:$A$2516,A9,'PLAN DE CORTE'!$B$5:$B$2516,B9) -> 68.125343 | L9: =IF(G9>0,J9/G9,0) -> 0.13093863 | M9: =G9*INDEX(PARÁMETROS!$B$93:$B$97,MATCH(B9,PARÁMETROS!$A$93:$A$97,0)) -> 1508.625
A10: Subtotal CIMENTACIÓN | C10: =SUM(C5:C9) -> 753 | D10: =SUM(D5:D9) -> 1578.652 | E10: =SUM(E5:E9) -> 2390.6276 | F10: =SUM(F5:F9) -> 191 | G10: =SUM(G5:G9) -> 1719 | H10: =SUM(H5:H9) -> 1585.5523 | I10: =SUM(I5:I9) -> 6.9003241 | J10: =SUM(J5:J9) -> 133.44768 | K10: =SUM(K5:K9) -> 98.81218 | L10: =IF(G10>0,J10/G10,0) -> 0.077630992 | M10: =SUM(M5:M9) -> 2661.309
A11: NIVEL 1 | B11: 1/4 | C11: =SUMIFS('DATOS MODELO'!$D$232:$D$279,'DATOS MODELO'!$A$232:$A$279,A11,'DATOS MODELO'!$C$232:$C$279,B11) -> 0 | D11: =SUMIFS('DATOS MODELO'!$E$232:$E$279,'DATOS MODELO'!$A$232:$A$279,A11,'DATOS MODELO'!$C$232:$C$279,B11) -> 0 | E11: =D11*INDEX(PARÁMETROS!$B$93:$B$97,MATCH(B11,PARÁMETROS!$A$93:$A$97,0)) -> 0 | F11: =COUNTIFS('PLAN DE CORTE'!$A$5:$A$2516,A11,'PLAN DE CORTE'!$B$5:$B$2516,B11) -> 0 | G11: =F11*9 -> 0 | H11: =SUMIFS('PLAN DE CORTE'!$F$5:$F$2516,'PLAN DE CORTE'!$A$5:$A$2516,A11,'PLAN DE CORTE'!$B$5:$B$2516,B11) -> 0 | I11: =H11-D11 -> 0 | J11: =G11-H11 -> 0 | K11: =SUMIFS('PLAN DE CORTE'!$H$5:$H$2516,'PLAN DE CORTE'!$A$5:$A$2516,A11,'PLAN DE CORTE'!$B$5:$B$2516,B11) -> 0 | L11: =IF(G11>0,J11/G11,0) -> 0 | M11: =G11*INDEX(PARÁMETROS!$B$93:$B$97,MATCH(B11,PARÁMETROS!$A$93:$A$97,0)) -> 0
A12: NIVEL 1 | B12: 3/8 | C12: =SUMIFS('DATOS MODELO'!$D$232:$D$279,'DATOS MODELO'!$A$232:$A$279,A12,'DATOS MODELO'!$C$232:$C$279,B12) -> 762 | D12: =SUMIFS('DATOS MODELO'!$E$232:$E$279,'DATOS MODELO'!$A$232:$A$279,A12,'DATOS MODELO'!$C$232:$C$279,B12) -> 735.885 | E12: =D12*INDEX(PARÁMETROS!$B$93:$B$97,MATCH(B12,PARÁMETROS!$A$93:$A$97,0)) -> 412.0956 | F12: =COUNTIFS('PLAN DE CORTE'!$A$5:$A$2516,A12,'PLAN DE CORTE'!$B$5:$B$2516,B12) -> 84 | G12: =F12*9 -> 756 | H12: =SUMIFS('PLAN DE CORTE'!$F$5:$F$2516,'PLAN DE CORTE'!$A$5:$A$2516,A12,'PLAN DE CORTE'!$B$5:$B$2516,B12) -> 735.88537 | I12: =H12-D12 -> 0.00037041882 | J12: =G12-H12 -> 20.11463 | K12: =SUMIFS('PLAN DE CORTE'!$H$5:$H$2516,'PLAN DE CORTE'!$A$5:$A$2516,A12,'PLAN DE CORTE'!$B$5:$B$2516,B12) -> 0 | L12: =IF(G12>0,J12/G12,0) -> 0.026606653 | M12: =G12*INDEX(PARÁMETROS!$B$93:$B$97,MATCH(B12,PARÁMETROS!$A$93:$A$97,0)) -> 423.36
A13: NIVEL 1 | B13: 1/2 | C13: =SUMIFS('DATOS MODELO'!$D$232:$D$279,'DATOS MODELO'!$A$232:$A$279,A13,'DATOS MODELO'!$C$232:$C$279,B13) -> 20 | D13: =SUMIFS('DATOS MODELO'!$E$232:$E$279,'DATOS MODELO'!$A$232:$A$279,A13,'DATOS MODELO'!$C$232:$C$279,B13) -> 73.554 | E13: =D13*INDEX(PARÁMETROS!$B$93:$B$97,MATCH(B13,PARÁMETROS!$A$93:$A$97,0)) -> 73.112676 | F13: =COUNTIFS('PLAN DE CORTE'!$A$5:$A$2516,A13,'PLAN DE CORTE'!$B$5:$B$2516,B13) -> 10 | G13: =F13*9 -> 90 | H13: =SUMIFS('PLAN DE CORTE'!$F$5:$F$2516,'PLAN DE CORTE'!$A$5:$A$2516,A13,'PLAN DE CORTE'!$B$5:$B$2516,B13) -> 73.553938 | I13: =H13-D13 -> -6.2065479e-05 | J13: =G13-H13 -> 16.446062 | K13: =SUMIFS('PLAN DE CORTE'!$H$5:$H$2516,'PLAN DE CORTE'!$A$5:$A$2516,A13,'PLAN DE CORTE'!$B$5:$B$2516,B13) -> 16.446062 | L13: =IF(G13>0,J13/G13,0) -> 0.18273402 | M13: =G13*INDEX(PARÁMETROS!$B$93:$B$97,MATCH(B13,PARÁMETROS!$A$93:$A$97,0)) -> 89.46
A14: NIVEL 1 | B14: 5/8 | C14: =SUMIFS('DATOS MODELO'!$D$232:$D$279,'DATOS MODELO'!$A$232:$A$279,A14,'DATOS MODELO'!$C$232:$C$279,B14) -> 136 | D14: =SUMIFS('DATOS MODELO'!$E$232:$E$279,'DATOS MODELO'!$A$232:$A$279,A14,'DATOS MODELO'!$C$232:$C$279,B14) -> 515.651 | E14: =D14*INDEX(PARÁMETROS!$B$93:$B$97,MATCH(B14,PARÁMETROS!$A$93:$A$97,0)) -> 800.29035 | F14: =COUNTIFS('PLAN DE CORTE'!$A$5:$A$2516,A14,'PLAN DE CORTE'!$B$5:$B$2516,B14) -> 68 | G14: =F14*9 -> 612 | H14: =SUMIFS('PLAN DE CORTE'!$F$5:$F$2516,'PLAN DE CORTE'!$A$5:$A$2516,A14,'PLAN DE CORTE'!$B$5:$B$2516,B14) -> 515.65132 | I14: =H14-D14 -> 0.00032244343 | J14: =G14-H14 -> 96.348678 | K14: =SUMIFS('PLAN DE CORTE'!$H$5:$H$2516,'PLAN DE CORTE'!$A$5:$A$2516,A14,'PLAN DE CORTE'!$B$5:$B$2516,B14) -> 96.348678 | L14: =IF(G14>0,J14/G14,0) -> 0.15743248 | M14: =G14*INDEX(PARÁMETROS!$B$93:$B$97,MATCH(B14,PARÁMETROS!$A$93:$A$97,0)) -> 949.824
A15: NIVEL 1 | B15: 3/4 | C15: =SUMIFS('DATOS MODELO'!$D$232:$D$279,'DATOS MODELO'!$A$232:$A$279,A15,'DATOS MODELO'!$C$232:$C$279,B15) -> 0 | D15: =SUMIFS('DATOS MODELO'!$E$232:$E$279,'DATOS MODELO'!$A$232:$A$279,A15,'DATOS MODELO'!$C$232:$C$279,B15) -> 0 | E15: =D15*INDEX(PARÁMETROS!$B$93:$B$97,MATCH(B15,PARÁMETROS!$A$93:$A$97,0)) -> 0 | F15: =COUNTIFS('PLAN DE CORTE'!$A$5:$A$2516,A15,'PLAN DE CORTE'!$B$5:$B$2516,B15) -> 0 | G15: =F15*9 -> 0 | H15: =SUMIFS('PLAN DE CORTE'!$F$5:$F$2516,'PLAN DE CORTE'!$A$5:$A$2516,A15,'PLAN DE CORTE'!$B$5:$B$2516,B15) -> 0 | I15: =H15-D15 -> 0 | J15: =G15-H15 -> 0 | K15: =SUMIFS('PLAN DE CORTE'!$H$5:$H$2516,'PLAN DE CORTE'!$A$5:$A$2516,A15,'PLAN DE CORTE'!$B$5:$B$2516,B15) -> 0 | L15: =IF(G15>0,J15/G15,0) -> 0 | M15: =G15*INDEX(PARÁMETROS!$B$93:$B$97,MATCH(B15,PARÁMETROS!$A$93:$A$97,0)) -> 0
A16: Subtotal NIVEL 1 | C16: =SUM(C11:C15) -> 918 | D16: =SUM(D11:D15) -> 1325.09 | E16: =SUM(E11:E15) -> 1285.4986 | F16: =SUM(F11:F15) -> 162 | G16: =SUM(G11:G15) -> 1458 | H16: =SUM(H11:H15) -> 1325.0906 | I16: =SUM(I11:I15) -> 0.00063079676 | J16: =SUM(J11:J15) -> 132.90937 | K16: =SUM(K11:K15) -> 112.79474 | L16: =IF(G16>0,J16/G16,0) -> 0.091158689 | M16: =SUM(M11:M15) -> 1462.644
A17: NIVEL 2 | B17: 1/4 | C17: =SUMIFS('DATOS MODELO'!$D$232:$D$279,'DATOS MODELO'!$A$232:$A$279,A17,'DATOS MODELO'!$C$232:$C$279,B17) -> 228 | D17: =SUMIFS('DATOS MODELO'!$E$232:$E$279,'DATOS MODELO'!$A$232:$A$279,A17,'DATOS MODELO'!$C$232:$C$279,B17) -> 839.284 | E17: =D17*INDEX(PARÁMETROS!$B$93:$B$97,MATCH(B17,PARÁMETROS!$A$93:$A$97,0)) -> 209.821 | F17: =COUNTIFS('PLAN DE CORTE'!$A$5:$A$2516,A17,'PLAN DE CORTE'!$B$5:$B$2516,B17) -> 110 | G17: =F17*9 -> 990 | H17: =SUMIFS('PLAN DE CORTE'!$F$5:$F$2516,'PLAN DE CORTE'!$A$5:$A$2516,A17,'PLAN DE CORTE'!$B$5:$B$2516,B17) -> 839.28397 | I17: =H17-D17 -> -2.8841426e-05 | J17: =G17-H17 -> 150.71603 | K17: =SUMIFS('PLAN DE CORTE'!$H$5:$H$2516,'PLAN DE CORTE'!$A$5:$A$2516,A17,'PLAN DE CORTE'!$B$5:$B$2516,B17) -> 128.52286 | L17: =IF(G17>0,J17/G17,0) -> 0.15223841 | M17: =G17*INDEX(PARÁMETROS!$B$93:$B$97,MATCH(B17,PARÁMETROS!$A$93:$A$97,0)) -> 247.5
A18: NIVEL 2 | B18: 3/8 | C18: =SUMIFS('DATOS MODELO'!$D$232:$D$279,'DATOS MODELO'!$A$232:$A$279,A18,'DATOS MODELO'!$C$232:$C$279,B18) -> 2130 | D18: =SUMIFS('DATOS MODELO'!$E$232:$E$279,'DATOS MODELO'!$A$232:$A$279,A18,'DATOS MODELO'!$C$232:$C$279,B18) -> 2448.966 | E18: =D18*INDEX(PARÁMETROS!$B$93:$B$97,MATCH(B18,PARÁMETROS!$A$93:$A$97,0)) -> 1371.421 | F18: =COUNTIFS('PLAN DE CORTE'!$A$5:$A$2516,A18,'PLAN DE CORTE'!$B$5:$B$2516,B18) -> 278 | G18: =F18*9 -> 2502 | H18: =SUMIFS('PLAN DE CORTE'!$F$5:$F$2516,'PLAN DE CORTE'!$A$5:$A$2516,A18,'PLAN DE CORTE'!$B$5:$B$2516,B18) -> 2448.966 | I18: =H18-D18 -> -2.2521553e-05 | J18: =G18-H18 -> 53.034023 | K18: =SUMIFS('PLAN DE CORTE'!$H$5:$H$2516,'PLAN DE CORTE'!$A$5:$A$2516,A18,'PLAN DE CORTE'!$B$5:$B$2516,B18) -> 1.9343023 | L18: =IF(G18>0,J18/G18,0) -> 0.021196652 | M18: =G18*INDEX(PARÁMETROS!$B$93:$B$97,MATCH(B18,PARÁMETROS!$A$93:$A$97,0)) -> 1401.12
A19: NIVEL 2 | B19: 1/2 | C19: =SUMIFS('DATOS MODELO'!$D$232:$D$279,'DATOS MODELO'!$A$232:$A$279,A19,'DATOS MODELO'!$C$232:$C$279,B19) -> 80 | D19: =SUMIFS('DATOS MODELO'!$E$232:$E$279,'DATOS MODELO'!$A$232:$A$279,A19,'DATOS MODELO'!$C$232:$C$279,B19) -> 317.822 | E19: =D19*INDEX(PARÁMETROS!$B$93:$B$97,MATCH(B19,PARÁMETROS!$A$93:$A$97,0)) -> 315.91507 | F19: =COUNTIFS('PLAN DE CORTE'!$A$5:$A$2516,A19,'PLAN DE CORTE'!$B$5:$B$2516,B19) -> 42 | G19: =F19*9 -> 378 | H19: =SUMIFS('PLAN DE CORTE'!$F$5:$F$2516,'PLAN DE CORTE'!$A$5:$A$2516,A19,'PLAN DE CORTE'!$B$5:$B$2516,B19) -> 317.82183 | I19: =H19-D19 -> -0.00016614448 | J19: =G19-H19 -> 60.178166 | K19: =SUMIFS('PLAN DE CORTE'!$H$5:$H$2516,'PLAN DE CORTE'!$A$5:$A$2516,A19,'PLAN DE CORTE'!$B$5:$B$2516,B19) -> 53.836223 | L19: =IF(G19>0,J19/G19,0) -> 0.1592015 | M19: =G19*INDEX(PARÁMETROS!$B$93:$B$97,MATCH(B19,PARÁMETROS!$A$93:$A$97,0)) -> 375.732
A20: NIVEL 2 | B20: 5/8 | C20: =SUMIFS('DATOS MODELO'!$D$232:$D$279,'DATOS MODELO'!$A$232:$A$279,A20,'DATOS MODELO'!$C$232:$C$279,B20) -> 142 | D20: =SUMIFS('DATOS MODELO'!$E$232:$E$279,'DATOS MODELO'!$A$232:$A$279,A20,'DATOS MODELO'!$C$232:$C$279,B20) -> 522.368 | E20: =D20*INDEX(PARÁMETROS!$B$93:$B$97,MATCH(B20,PARÁMETROS!$A$93:$A$97,0)) -> 810.71514 | F20: =COUNTIFS('PLAN DE CORTE'!$A$5:$A$2516,A20,'PLAN DE CORTE'!$B$5:$B$2516,B20) -> 71 | G20: =F20*9 -> 639 | H20: =SUMIFS('PLAN DE CORTE'!$F$5:$F$2516,'PLAN DE CORTE'!$A$5:$A$2516,A20,'PLAN DE CORTE'!$B$5:$B$2516,B20) -> 522.36794 | I20: =H20-D20 -> -6.4116981e-05 | J20: =G20-H20 -> 116.63206 | K20: =SUMIFS('PLAN DE CORTE'!$H$5:$H$2516,'PLAN DE CORTE'!$A$5:$A$2516,A20,'PLAN DE CORTE'!$B$5:$B$2516,B20) -> 115.40449 | L20: =IF(G20>0,J20/G20,0) -> 0.18252279 | M20: =G20*INDEX(PARÁMETROS!$B$93:$B$97,MATCH(B20,PARÁMETROS!$A$93:$A$97,0)) -> 991.728
A21: NIVEL 2 | B21: 3/4 | C21: =SUMIFS('DATOS MODELO'!$D$232:$D$279,'DATOS MODELO'!$A$232:$A$279,A21,'DATOS MODELO'!$C$232:$C$279,B21) -> 130 | D21: =SUMIFS('DATOS MODELO'!$E$232:$E$279,'DATOS MODELO'!$A$232:$A$279,A21,'DATOS MODELO'!$C$232:$C$279,B21) -> 721.345 | E21: =D21*INDEX(PARÁMETROS!$B$93:$B$97,MATCH(B21,PARÁMETROS!$A$93:$A$97,0)) -> 1612.2061 | F21: =COUNTIFS('PLAN DE CORTE'!$A$5:$A$2516,A21,'PLAN DE CORTE'!$B$5:$B$2516,B21) -> 90 | G21: =F21*9 -> 810 | H21: =SUMIFS('PLAN DE CORTE'!$F$5:$F$2516,'PLAN DE CORTE'!$A$5:$A$2516,A21,'PLAN DE CORTE'!$B$5:$B$2516,B21) -> 735.14467 | I21: =H21-D21 -> 13.799671 | J21: =G21-H21 -> 74.855329 | K21: =SUMIFS('PLAN DE CORTE'!$H$5:$H$2516,'PLAN DE CORTE'!$A$5:$A$2516,A21,'PLAN DE CORTE'!$B$5:$B$2516,B21) -> 57.825026 | L21: =IF(G21>0,J21/G21,0) -> 0.092413987 | M21: =G21*INDEX(PARÁMETROS!$B$93:$B$97,MATCH(B21,PARÁMETROS!$A$93:$A$97,0)) -> 1810.35
A22: Subtotal NIVEL 2 | C22: =SUM(C17:C21) -> 2710 | D22: =SUM(D17:D21) -> 4849.785 | E22: =SUM(E17:E21) -> 4320.0782 | F22: =SUM(F17:F21) -> 591 | G22: =SUM(G17:G21) -> 5319 | H22: =SUM(H17:H21) -> 4863.5844 | I22: =SUM(I17:I21) -> 13.799389 | J22: =SUM(J17:J21) -> 455.41561 | K22: =SUM(K17:K21) -> 357.5229 | L22: =IF(G22>0,J22/G22,0) -> 0.085620532 | M22: =SUM(M17:M21) -> 4826.43
A23: NIVEL 3 | B23: 1/4 | C23: =SUMIFS('DATOS MODELO'!$D$232:$D$279,'DATOS MODELO'!$A$232:$A$279,A23,'DATOS MODELO'!$C$232:$C$279,B23) -> 228 | D23: =SUMIFS('DATOS MODELO'!$E$232:$E$279,'DATOS MODELO'!$A$232:$A$279,A23,'DATOS MODELO'!$C$232:$C$279,B23) -> 839.284 | E23: =D23*INDEX(PARÁMETROS!$B$93:$B$97,MATCH(B23,PARÁMETROS!$A$93:$A$97,0)) -> 209.821 | F23: =COUNTIFS('PLAN DE CORTE'!$A$5:$A$2516,A23,'PLAN DE CORTE'!$B$5:$B$2516,B23) -> 110 | G23: =F23*9 -> 990 | H23: =SUMIFS('PLAN DE CORTE'!$F$5:$F$2516,'PLAN DE CORTE'!$A$5:$A$2516,A23,'PLAN DE CORTE'!$B$5:$B$2516,B23) -> 839.28397 | I23: =H23-D23 -> -2.8841426e-05 | J23: =G23-H23 -> 150.71603 | K23: =SUMIFS('PLAN DE CORTE'!$H$5:$H$2516,'PLAN DE CORTE'!$A$5:$A$2516,A23,'PLAN DE CORTE'!$B$5:$B$2516,B23) -> 128.52286 | L23: =IF(G23>0,J23/G23,0) -> 0.15223841 | M23: =G23*INDEX(PARÁMETROS!$B$93:$B$97,MATCH(B23,PARÁMETROS!$A$93:$A$97,0)) -> 247.5
A24: NIVEL 3 | B24: 3/8 | C24: =SUMIFS('DATOS MODELO'!$D$232:$D$279,'DATOS MODELO'!$A$232:$A$279,A24,'DATOS MODELO'!$C$232:$C$279,B24) -> 1856 | D24: =SUMIFS('DATOS MODELO'!$E$232:$E$279,'DATOS MODELO'!$A$232:$A$279,A24,'DATOS MODELO'!$C$232:$C$279,B24) -> 2173.839 | E24: =D24*INDEX(PARÁMETROS!$B$93:$B$97,MATCH(B24,PARÁMETROS!$A$93:$A$97,0)) -> 1217.3498 | F24: =COUNTIFS('PLAN DE CORTE'!$A$5:$A$2516,A24,'PLAN DE CORTE'!$B$5:$B$2516,B24) -> 247 | G24: =F24*9 -> 2223 | H24: =SUMIFS('PLAN DE CORTE'!$F$5:$F$2516,'PLAN DE CORTE'!$A$5:$A$2516,A24,'PLAN DE CORTE'!$B$5:$B$2516,B24) -> 2173.838 | I24: =H24-D24 -> -0.00097337408 | J24: =G24-H24 -> 49.161973 | K24: =SUMIFS('PLAN DE CORTE'!$H$5:$H$2516,'PLAN DE CORTE'!$A$5:$A$2516,A24,'PLAN DE CORTE'!$B$5:$B$2516,B24) -> 4.2895348 | L24: =IF(G24>0,J24/G24,0) -> 0.022115148 | M24: =G24*INDEX(PARÁMETROS!$B$93:$B$97,MATCH(B24,PARÁMETROS!$A$93:$A$97,0)) -> 1244.88
A25: NIVEL 3 | B25: 1/2 | C25: =SUMIFS('DATOS MODELO'!$D$232:$D$279,'DATOS MODELO'!$A$232:$A$279,A25,'DATOS MODELO'!$C$232:$C$279,B25) -> 80 | D25: =SUMIFS('DATOS MODELO'!$E$232:$E$279,'DATOS MODELO'!$A$232:$A$279,A25,'DATOS MODELO'!$C$232:$C$279,B25) -> 311.818 | E25: =D25*INDEX(PARÁMETROS!$B$93:$B$97,MATCH(B25,PARÁMETROS!$A$93:$A$97,0)) -> 309.94709 | F25: =COUNTIFS('PLAN DE CORTE'!$A$5:$A$2516,A25,'PLAN DE CORTE'!$B$5:$B$2516,B25) -> 39 | G25: =F25*9 -> 351 | H25: =SUMIFS('PLAN DE CORTE'!$F$5:$F$2516,'PLAN DE CORTE'!$A$5:$A$2516,A25,'PLAN DE CORTE'!$B$5:$B$2516,B25) -> 311.81762 | I25: =H25-D25 -> -0.00038119824 | J25: =G25-H25 -> 39.182381 | K25: =SUMIFS('PLAN DE CORTE'!$H$5:$H$2516,'PLAN DE CORTE'!$A$5:$A$2516,A25,'PLAN DE CORTE'!$B$5:$B$2516,B25) -> 30.063499 | L25: =IF(G25>0,J25/G25,0) -> 0.11163072 | M25: =G25*INDEX(PARÁMETROS!$B$93:$B$97,MATCH(B25,PARÁMETROS!$A$93:$A$97,0)) -> 348.894
A26: NIVEL 3 | B26: 5/8 | C26: =SUMIFS('DATOS MODELO'!$D$232:$D$279,'DATOS MODELO'!$A$232:$A$279,A26,'DATOS MODELO'!$C$232:$C$279,B26) -> 142 | D26: =SUMIFS('DATOS MODELO'!$E$232:$E$279,'DATOS MODELO'!$A$232:$A$279,A26,'DATOS MODELO'!$C$232:$C$279,B26) -> 481.568 | E26: =D26*INDEX(PARÁMETROS!$B$93:$B$97,MATCH(B26,PARÁMETROS!$A$93:$A$97,0)) -> 747.39354 | F26: =COUNTIFS('PLAN DE CORTE'!$A$5:$A$2516,A26,'PLAN DE CORTE'!$B$5:$B$2516,B26) -> 71 | G26: =F26*9 -> 639 | H26: =SUMIFS('PLAN DE CORTE'!$F$5:$F$2516,'PLAN DE CORTE'!$A$5:$A$2516,A26,'PLAN DE CORTE'!$B$5:$B$2516,B26) -> 481.56794 | I26: =H26-D26 -> -6.4116981e-05 | J26: =G26-H26 -> 157.43206 | K26: =SUMIFS('PLAN DE CORTE'!$H$5:$H$2516,'PLAN DE CORTE'!$A$5:$A$2516,A26,'PLAN DE CORTE'!$B$5:$B$2516,B26) -> 156.20449 | L26: =IF(G26>0,J26/G26,0) -> 0.24637256 | M26: =G26*INDEX(PARÁMETROS!$B$93:$B$97,MATCH(B26,PARÁMETROS!$A$93:$A$97,0)) -> 991.728
A27: NIVEL 3 | B27: 3/4 | C27: =SUMIFS('DATOS MODELO'!$D$232:$D$279,'DATOS MODELO'!$A$232:$A$279,A27,'DATOS MODELO'!$C$232:$C$279,B27) -> 102 | D27: =SUMIFS('DATOS MODELO'!$E$232:$E$279,'DATOS MODELO'!$A$232:$A$279,A27,'DATOS MODELO'!$C$232:$C$279,B27) -> 560.78 | E27: =D27*INDEX(PARÁMETROS!$B$93:$B$97,MATCH(B27,PARÁMETROS!$A$93:$A$97,0)) -> 1253.3433 | F27: =COUNTIFS('PLAN DE CORTE'!$A$5:$A$2516,A27,'PLAN DE CORTE'!$B$5:$B$2516,B27) -> 71 | G27: =F27*9 -> 639 | H27: =SUMIFS('PLAN DE CORTE'!$F$5:$F$2516,'PLAN DE CORTE'!$A$5:$A$2516,A27,'PLAN DE CORTE'!$B$5:$B$2516,B27) -> 569.97958 | I27: =H27-D27 -> 9.1995757 | J27: =G27-H27 -> 69.020424 | K27: =SUMIFS('PLAN DE CORTE'!$H$5:$H$2516,'PLAN DE CORTE'!$A$5:$A$2516,A27,'PLAN DE CORTE'!$B$5:$B$2516,B27) -> 53.789751 | L27: =IF(G27>0,J27/G27,0) -> 0.10801318 | M27: =G27*INDEX(PARÁMETROS!$B$93:$B$97,MATCH(B27,PARÁMETROS!$A$93:$A$97,0)) -> 1428.165
A28: Subtotal NIVEL 3 | C28: =SUM(C23:C27) -> 2408 | D28: =SUM(D23:D27) -> 4367.289 | E28: =SUM(E23:E27) -> 3737.8548 | F28: =SUM(F23:F27) -> 538 | G28: =SUM(G23:G27) -> 4842 | H28: =SUM(H23:H27) -> 4376.4871 | I28: =SUM(I23:I27) -> 9.1981282 | J28: =SUM(J23:J27) -> 465.51287 | K28: =SUM(K23:K27) -> 372.87013 | L28: =IF(G28>0,J28/G28,0) -> 0.096140618 | M28: =SUM(M23:M27) -> 4261.167
A29: NIVEL 4 | B29: 1/4 | C29: =SUMIFS('DATOS MODELO'!$D$232:$D$279,'DATOS MODELO'!$A$232:$A$279,A29,'DATOS MODELO'!$C$232:$C$279,B29) -> 228 | D29: =SUMIFS('DATOS MODELO'!$E$232:$E$279,'DATOS MODELO'!$A$232:$A$279,A29,'DATOS MODELO'!$C$232:$C$279,B29) -> 839.284 | E29: =D29*INDEX(PARÁMETROS!$B$93:$B$97,MATCH(B29,PARÁMETROS!$A$93:$A$97,0)) -> 209.821 | F29: =COUNTIFS('PLAN DE CORTE'!$A$5:$A$2516,A29,'PLAN DE CORTE'!$B$5:$B$2516,B29) -> 110 | G29: =F29*9 -> 990 | H29: =SUMIFS('PLAN DE CORTE'!$F$5:$F$2516,'PLAN DE CORTE'!$A$5:$A$2516,A29,'PLAN DE CORTE'!$B$5:$B$2516,B29) -> 839.28397 | I29: =H29-D29 -> -2.8841426e-05 | J29: =G29-H29 -> 150.71603 | K29: =SUMIFS('PLAN DE CORTE'!$H$5:$H$2516,'PLAN DE CORTE'!$A$5:$A$2516,A29,'PLAN DE CORTE'!$B$5:$B$2516,B29) -> 128.52286 | L29: =IF(G29>0,J29/G29,0) -> 0.15223841 | M29: =G29*INDEX(PARÁMETROS!$B$93:$B$97,MATCH(B29,PARÁMETROS!$A$93:$A$97,0)) -> 247.5
A30: NIVEL 4 | B30: 3/8 | C30: =SUMIFS('DATOS MODELO'!$D$232:$D$279,'DATOS MODELO'!$A$232:$A$279,A30,'DATOS MODELO'!$C$232:$C$279,B30) -> 1856 | D30: =SUMIFS('DATOS MODELO'!$E$232:$E$279,'DATOS MODELO'!$A$232:$A$279,A30,'DATOS MODELO'!$C$232:$C$279,B30) -> 2175.53 | E30: =D30*INDEX(PARÁMETROS!$B$93:$B$97,MATCH(B30,PARÁMETROS!$A$93:$A$97,0)) -> 1218.2968 | F30: =COUNTIFS('PLAN DE CORTE'!$A$5:$A$2516,A30,'PLAN DE CORTE'!$B$5:$B$2516,B30) -> 247 | G30: =F30*9 -> 2223 | H30: =SUMIFS('PLAN DE CORTE'!$F$5:$F$2516,'PLAN DE CORTE'!$A$5:$A$2516,A30,'PLAN DE CORTE'!$B$5:$B$2516,B30) -> 2175.5291 | I30: =H30-D30 -> -0.00091061336 | J30: =G30-H30 -> 47.470911 | K30: =SUMIFS('PLAN DE CORTE'!$H$5:$H$2516,'PLAN DE CORTE'!$A$5:$A$2516,A30,'PLAN DE CORTE'!$B$5:$B$2516,B30) -> 3.1119186 | L30: =IF(G30>0,J30/G30,0) -> 0.021354436 | M30: =G30*INDEX(PARÁMETROS!$B$93:$B$97,MATCH(B30,PARÁMETROS!$A$93:$A$97,0)) -> 1244.88
A31: NIVEL 4 | B31: 1/2 | C31: =SUMIFS('DATOS MODELO'!$D$232:$D$279,'DATOS MODELO'!$A$232:$A$279,A31,'DATOS MODELO'!$C$232:$C$279,B31) -> 80 | D31: =SUMIFS('DATOS MODELO'!$E$232:$E$279,'DATOS MODELO'!$A$232:$A$279,A31,'DATOS MODELO'!$C$232:$C$279,B31) -> 311.818 | E31: =D31*INDEX(PARÁMETROS!$B$93:$B$97,MATCH(B31,PARÁMETROS!$A$93:$A$97,0)) -> 309.94709 | F31: =COUNTIFS('PLAN DE CORTE'!$A$5:$A$2516,A31,'PLAN DE CORTE'!$B$5:$B$2516,B31) -> 39 | G31: =F31*9 -> 351 | H31: =SUMIFS('PLAN DE CORTE'!$F$5:$F$2516,'PLAN DE CORTE'!$A$5:$A$2516,A31,'PLAN DE CORTE'!$B$5:$B$2516,B31) -> 311.81762 | I31: =H31-D31 -> -0.00038119824 | J31: =G31-H31 -> 39.182381 | K31: =SUMIFS('PLAN DE CORTE'!$H$5:$H$2516,'PLAN DE CORTE'!$A$5:$A$2516,A31,'PLAN DE CORTE'!$B$5:$B$2516,B31) -> 30.063499 | L31: =IF(G31>0,J31/G31,0) -> 0.11163072 | M31: =G31*INDEX(PARÁMETROS!$B$93:$B$97,MATCH(B31,PARÁMETROS!$A$93:$A$97,0)) -> 348.894
A32: NIVEL 4 | B32: 5/8 | C32: =SUMIFS('DATOS MODELO'!$D$232:$D$279,'DATOS MODELO'!$A$232:$A$279,A32,'DATOS MODELO'!$C$232:$C$279,B32) -> 142 | D32: =SUMIFS('DATOS MODELO'!$E$232:$E$279,'DATOS MODELO'!$A$232:$A$279,A32,'DATOS MODELO'!$C$232:$C$279,B32) -> 481.568 | E32: =D32*INDEX(PARÁMETROS!$B$93:$B$97,MATCH(B32,PARÁMETROS!$A$93:$A$97,0)) -> 747.39354 | F32: =COUNTIFS('PLAN DE CORTE'!$A$5:$A$2516,A32,'PLAN DE CORTE'!$B$5:$B$2516,B32) -> 71 | G32: =F32*9 -> 639 | H32: =SUMIFS('PLAN DE CORTE'!$F$5:$F$2516,'PLAN DE CORTE'!$A$5:$A$2516,A32,'PLAN DE CORTE'!$B$5:$B$2516,B32) -> 481.56794 | I32: =H32-D32 -> -6.4116981e-05 | J32: =G32-H32 -> 157.43206 | K32: =SUMIFS('PLAN DE CORTE'!$H$5:$H$2516,'PLAN DE CORTE'!$A$5:$A$2516,A32,'PLAN DE CORTE'!$B$5:$B$2516,B32) -> 156.20449 | L32: =IF(G32>0,J32/G32,0) -> 0.24637256 | M32: =G32*INDEX(PARÁMETROS!$B$93:$B$97,MATCH(B32,PARÁMETROS!$A$93:$A$97,0)) -> 991.728
A33: NIVEL 4 | B33: 3/4 | C33: =SUMIFS('DATOS MODELO'!$D$232:$D$279,'DATOS MODELO'!$A$232:$A$279,A33,'DATOS MODELO'!$C$232:$C$279,B33) -> 100 | D33: =SUMIFS('DATOS MODELO'!$E$232:$E$279,'DATOS MODELO'!$A$232:$A$279,A33,'DATOS MODELO'!$C$232:$C$279,B33) -> 548.913 | E33: =D33*INDEX(PARÁMETROS!$B$93:$B$97,MATCH(B33,PARÁMETROS!$A$93:$A$97,0)) -> 1226.8206 | F33: =COUNTIFS('PLAN DE CORTE'!$A$5:$A$2516,A33,'PLAN DE CORTE'!$B$5:$B$2516,B33) -> 69 | G33: =F33*9 -> 621 | H33: =SUMIFS('PLAN DE CORTE'!$F$5:$F$2516,'PLAN DE CORTE'!$A$5:$A$2516,A33,'PLAN DE CORTE'!$B$5:$B$2516,B33) -> 558.11291 | I33: =H33-D33 -> 9.199906 | J33: =G33-H33 -> 62.887094 | K33: =SUMIFS('PLAN DE CORTE'!$H$5:$H$2516,'PLAN DE CORTE'!$A$5:$A$2516,A33,'PLAN DE CORTE'!$B$5:$B$2516,B33) -> 48.514542 | L33: =IF(G33>0,J33/G33,0) -> 0.10126746 | M33: =G33*INDEX(PARÁMETROS!$B$93:$B$97,MATCH(B33,PARÁMETROS!$A$93:$A$97,0)) -> 1387.935
A34: Subtotal NIVEL 4 | C34: =SUM(C29:C33) -> 2406 | D34: =SUM(D29:D33) -> 4357.113 | E34: =SUM(E29:E33) -> 3712.279 | F34: =SUM(F29:F33) -> 536 | G34: =SUM(G29:G33) -> 4824 | H34: =SUM(H29:H33) -> 4366.3115 | I34: =SUM(I29:I33) -> 9.1985212 | J34: =SUM(J29:J33) -> 457.68848 | K34: =SUM(K29:K33) -> 366.41731 | L34: =IF(G34>0,J34/G34,0) -> 0.09487738 | M34: =SUM(M29:M33) -> 4220.937
A35: NIVEL 5 | B35: 1/4 | C35: =SUMIFS('DATOS MODELO'!$D$232:$D$279,'DATOS MODELO'!$A$232:$A$279,A35,'DATOS MODELO'!$C$232:$C$279,B35) -> 228 | D35: =SUMIFS('DATOS MODELO'!$E$232:$E$279,'DATOS MODELO'!$A$232:$A$279,A35,'DATOS MODELO'!$C$232:$C$279,B35) -> 839.282 | E35: =D35*INDEX(PARÁMETROS!$B$93:$B$97,MATCH(B35,PARÁMETROS!$A$93:$A$97,0)) -> 209.8205 | F35: =COUNTIFS('PLAN DE CORTE'!$A$5:$A$2516,A35,'PLAN DE CORTE'!$B$5:$B$2516,B35) -> 110 | G35: =F35*9 -> 990 | H35: =SUMIFS('PLAN DE CORTE'!$F$5:$F$2516,'PLAN DE CORTE'!$A$5:$A$2516,A35,'PLAN DE CORTE'!$B$5:$B$2516,B35) -> 839.28247 | I35: =H35-D35 -> 0.00046578223 | J35: =G35-H35 -> 150.71753 | K35: =SUMIFS('PLAN DE CORTE'!$H$5:$H$2516,'PLAN DE CORTE'!$A$5:$A$2516,A35,'PLAN DE CORTE'!$B$5:$B$2516,B35) -> 128.52436 | L35: =IF(G35>0,J35/G35,0) -> 0.15223993 | M35: =G35*INDEX(PARÁMETROS!$B$93:$B$97,MATCH(B35,PARÁMETROS!$A$93:$A$97,0)) -> 247.5
A36: NIVEL 5 | B36: 3/8 | C36: =SUMIFS('DATOS MODELO'!$D$232:$D$279,'DATOS MODELO'!$A$232:$A$279,A36,'DATOS MODELO'!$C$232:$C$279,B36) -> 1856 | D36: =SUMIFS('DATOS MODELO'!$E$232:$E$279,'DATOS MODELO'!$A$232:$A$279,A36,'DATOS MODELO'!$C$232:$C$279,B36) -> 2175.53 | E36: =D36*INDEX(PARÁMETROS!$B$93:$B$97,MATCH(B36,PARÁMETROS!$A$93:$A$97,0)) -> 1218.2968 | F36: =COUNTIFS('PLAN DE CORTE'!$A$5:$A$2516,A36,'PLAN DE CORTE'!$B$5:$B$2516,B36) -> 247 | G36: =F36*9 -> 2223 | H36: =SUMIFS('PLAN DE CORTE'!$F$5:$F$2516,'PLAN DE CORTE'!$A$5:$A$2516,A36,'PLAN DE CORTE'!$B$5:$B$2516,B36) -> 2175.5291 | I36: =H36-D36 -> -0.00091061336 | J36: =G36-H36 -> 47.470911 | K36: =SUMIFS('PLAN DE CORTE'!$H$5:$H$2516,'PLAN DE CORTE'!$A$5:$A$2516,A36,'PLAN DE CORTE'!$B$5:$B$2516,B36) -> 3.1119186 | L36: =IF(G36>0,J36/G36,0) -> 0.021354436 | M36: =G36*INDEX(PARÁMETROS!$B$93:$B$97,MATCH(B36,PARÁMETROS!$A$93:$A$97,0)) -> 1244.88
A37: NIVEL 5 | B37: 1/2 | C37: =SUMIFS('DATOS MODELO'!$D$232:$D$279,'DATOS MODELO'!$A$232:$A$279,A37,'DATOS MODELO'!$C$232:$C$279,B37) -> 80 | D37: =SUMIFS('DATOS MODELO'!$E$232:$E$279,'DATOS MODELO'!$A$232:$A$279,A37,'DATOS MODELO'!$C$232:$C$279,B37) -> 284.36 | E37: =D37*INDEX(PARÁMETROS!$B$93:$B$97,MATCH(B37,PARÁMETROS!$A$93:$A$97,0)) -> 282.65384 | F37: =COUNTIFS('PLAN DE CORTE'!$A$5:$A$2516,A37,'PLAN DE CORTE'!$B$5:$B$2516,B37) -> 35 | G37: =F37*9 -> 315 | H37: =SUMIFS('PLAN DE CORTE'!$F$5:$F$2516,'PLAN DE CORTE'!$A$5:$A$2516,A37,'PLAN DE CORTE'!$B$5:$B$2516,B37) -> 284.36027 | I37: =H37-D37 -> 0.00027179005 | J37: =G37-H37 -> 30.639728 | K37: =SUMIFS('PLAN DE CORTE'!$H$5:$H$2516,'PLAN DE CORTE'!$A$5:$A$2516,A37,'PLAN DE CORTE'!$B$5:$B$2516,B37) -> 23.198087 | L37: =IF(G37>0,J37/G37,0) -> 0.097268978 | M37: =G37*INDEX(PARÁMETROS!$B$93:$B$97,MATCH(B37,PARÁMETROS!$A$93:$A$97,0)) -> 313.11
A38: NIVEL 5 | B38: 5/8 | C38: =SUMIFS('DATOS MODELO'!$D$232:$D$279,'DATOS MODELO'!$A$232:$A$279,A38,'DATOS MODELO'!$C$232:$C$279,B38) -> 142 | D38: =SUMIFS('DATOS MODELO'!$E$232:$E$279,'DATOS MODELO'!$A$232:$A$279,A38,'DATOS MODELO'!$C$232:$C$279,B38) -> 280.154 | E38: =D38*INDEX(PARÁMETROS!$B$93:$B$97,MATCH(B38,PARÁMETROS!$A$93:$A$97,0)) -> 434.79901 | F38: =COUNTIFS('PLAN DE CORTE'!$A$5:$A$2516,A38,'PLAN DE CORTE'!$B$5:$B$2516,B38) -> 35 | G38: =F38*9 -> 315 | H38: =SUMIFS('PLAN DE CORTE'!$F$5:$F$2516,'PLAN DE CORTE'!$A$5:$A$2516,A38,'PLAN DE CORTE'!$B$5:$B$2516,B38) -> 280.15435 | I38: =H38-D38 -> 0.00035400651 | J38: =G38-H38 -> 34.845646 | K38: =SUMIFS('PLAN DE CORTE'!$H$5:$H$2516,'PLAN DE CORTE'!$A$5:$A$2516,A38,'PLAN DE CORTE'!$B$5:$B$2516,B38) -> 30.813936 | L38: =IF(G38>0,J38/G38,0) -> 0.1106211 | M38: =G38*INDEX(PARÁMETROS!$B$93:$B$97,MATCH(B38,PARÁMETROS!$A$93:$A$97,0)) -> 488.88
A39: NIVEL 5 | B39: 3/4 | C39: =SUMIFS('DATOS MODELO'!$D$232:$D$279,'DATOS MODELO'!$A$232:$A$279,A39,'DATOS MODELO'!$C$232:$C$279,B39) -> 98 | D39: =SUMIFS('DATOS MODELO'!$E$232:$E$279,'DATOS MODELO'!$A$232:$A$279,A39,'DATOS MODELO'!$C$232:$C$279,B39) -> 537.465 | E39: =D39*INDEX(PARÁMETROS!$B$93:$B$97,MATCH(B39,PARÁMETROS!$A$93:$A$97,0)) -> 1201.2343 | F39: =COUNTIFS('PLAN DE CORTE'!$A$5:$A$2516,A39,'PLAN DE CORTE'!$B$5:$B$2516,B39) -> 67 | G39: =F39*9 -> 603 | H39: =SUMIFS('PLAN DE CORTE'!$F$5:$F$2516,'PLAN DE CORTE'!$A$5:$A$2516,A39,'PLAN DE CORTE'!$B$5:$B$2516,B39) -> 546.66478 | I39: =H39-D39 -> 9.199775 | J39: =G39-H39 -> 56.335225 | K39: =SUMIFS('PLAN DE CORTE'!$H$5:$H$2516,'PLAN DE CORTE'!$A$5:$A$2516,A39,'PLAN DE CORTE'!$B$5:$B$2516,B39) -> 41.873864 | L39: =IF(G39>0,J39/G39,0) -> 0.093424917 | M39: =G39*INDEX(PARÁMETROS!$B$93:$B$97,MATCH(B39,PARÁMETROS!$A$93:$A$97,0)) -> 1347.705
A40: Subtotal NIVEL 5 | C40: =SUM(C35:C39) -> 2404 | D40: =SUM(D35:D39) -> 4116.791 | E40: =SUM(E35:E39) -> 3346.8044 | F40: =SUM(F35:F39) -> 494 | G40: =SUM(G35:G39) -> 4446 | H40: =SUM(H35:H39) -> 4125.991 | I40: =SUM(I35:I39) -> 9.199956 | J40: =SUM(J35:J39) -> 320.00904 | K40: =SUM(K35:K39) -> 227.52217 | L40: =IF(G40>0,J40/G40,0) -> 0.071976843 | M40: =SUM(M35:M39) -> 3642.075
A42: TOTAL POR DIÁMETRO
...

Sheet LISTA DE COMPRAS
A1: LISTA DE COMPRAS - CASCO ESTRUCTURAL (unidades comerciales, precios referenciales Cusco)
A2: Acero: unidad de compra = VARILLA de 9 m; los kg van solo como referencia. Alambres en kg.
A4: RESUMEN CONSOLIDADO (todos los niveles)
B5: Categoría | C5: Insumo | D5: Unidad de compra | E5: Cantidad requerida | F5: Cantidad a comprar | G5: Precio unitario (S/) | H5: Total (S/) | I5: Peso de referencia (kg) | J5: % del costo
B6: =INDEX(PARÁMETROS!$F$70:$F$89,MATCH(C6,PARÁMETROS!$A$70:$A$89,0)) -> Concreto | C6: Cemento Portland IP 42.5 kg | D6: =INDEX(PARÁMETROS!$B$70:$B$89,MATCH(C6,PARÁMETROS!$A$70:$A$89,0)) -> bolsa | E6: =SUMIFS($E$38:$E$182,$C$38:$C$182,C6) -> 1547.7451 | F6: =SUMIFS($F$38:$F$182,$C$38:$C$182,C6) -> 1552 | G6: =INDEX(PARÁMETROS!$C$70:$C$89,MATCH(C6,PARÁMETROS!$A$70:$A$89,0)) -> 27 | H6: =SUMIFS($H$38:$H$182,$C$38:$C$182,C6) -> 41904 | I6: =IF(SUMIFS($I$38:$I$182,$C$38:$C$182,C6)=0,"",SUMIFS($I$38:$I$182,$C$38:$C$182,C6)) | J6: =IF($H$26>0,H6/$H$26,0) -> 0.24519054
B7: =INDEX(PARÁMETROS!$F$70:$F$89,MATCH(C7,PARÁMETROS!$A$70:$A$89,0)) -> Concreto | C7: Arena gruesa | D7: =INDEX(PARÁMETROS!$B$70:$B$89,MATCH(C7,PARÁMETROS!$A$70:$A$89,0)) -> m³ | E7: =SUMIFS($E$38:$E$182,$C$38:$C$182,C7) -> 85.269933 | F7: =SUMIFS($F$38:$F$182,$C$38:$C$182,C7) -> 86.5 | G7: =INDEX(PARÁMETROS!$C$70:$C$89,MATCH(C7,PARÁMETROS!$A$70:$A$89,0)) -> 70 | H7: =SUMIFS($H$38:$H$182,$C$38:$C$182,C7) -> 6055 | I7: =IF(SUMIFS($I$38:$I$182,$C$38:$C$182,C7)=0,"",SUMIFS($I$38:$I$182,$C$38:$C$182,C7)) | J7: =IF($H$26>0,H7/$H$26,0) -> 0.035429284
B8: =INDEX(PARÁMETROS!$F$70:$F$89,MATCH(C8,PARÁMETROS!$A$70:$A$89,0)) -> Concreto | C8: Piedra chancada 1/2" | D8: =INDEX(PARÁMETROS!$B$70:$B$89,MATCH(C8,PARÁMETROS!$A$70:$A$89,0)) -> m³ | E8: =SUMIFS($E$38:$E$182,$C$38:$C$182,C8) -> 87.565645 | F8: =SUMIFS($F$38:$F$182,$C$38:$C$182,C8) -> 90 | G8: =INDEX(PARÁMETROS!$C$70:$C$89,MATCH(C8,PARÁMETROS!$A$70:$A$89,0)) -> 80 | H8: =SUMIFS($H$38:$H$182,$C$38:$C$182,C8) -> 7200 | I8: =IF(SUMIFS($I$38:$I$182,$C$38:$C$182,C8)=0,"",SUMIFS($I$38:$I$182,$C$38:$C$182,C8)) | J8: =IF($H$26>0,H8/$H$26,0) -> 0.042128959
B9: =INDEX(PARÁMETROS!$F$70:$F$89,MATCH(C9,PARÁMETROS!$A$70:$A$89,0)) -> Concreto | C9: Agua | D9: =INDEX(PARÁMETROS!$B$70:$B$89,MATCH(C9,PARÁMETROS!$A$70:$A$89,0)) -> m³ | E9: =SUMIFS($E$38:$E$182,$C$38:$C$182,C9) -> 30.312349 | F9: =SUMIFS($F$38:$F$182,$C$38:$C$182,C9) -> 32.5 | G9: =INDEX(PARÁMETROS!$C$70:$C$89,MATCH(C9,PARÁMETROS!$A$70:$A$89,0)) -> 7 | H9: =SUMIFS($H$38:$H$182,$C$38:$C$182,C9) -> 227.5 | I9: =IF(SUMIFS($I$38:$I$182,$C$38:$C$182,C9)=0,"",SUMIFS($I$38:$I$182,$C$38:$C$182,C9)) | J9: =IF($H$26>0,H9/$H$26,0) -> 0.0013311581
B10: =INDEX(PARÁMETROS!$F$70:$F$89,MATCH(C10,PARÁMETROS!$A$70:$A$89,0)) -> Concreto | C10: Casetón EPS 1.20x0.30x0.15 | D10: =INDEX(PARÁMETROS!$B$70:$B$89,MATCH(C10,PARÁMETROS!$A$70:$A$89,0)) -> und | E10: =SUMIFS($E$38:$E$182,$C$38:$C$182,C10) -> 596.33567 | F10: =SUMIFS($F$38:$F$182,$C$38:$C$182,C10) -> 600 | G10: =INDEX(PARÁMETROS!$C$70:$C$89,MATCH(C10,PARÁMETROS!$A$70:$A$89,0)) -> 12.9 | H10: =SUMIFS($H$38:$H$182,$C$38:$C$182,C10) -> 7740 | I10: =IF(SUMIFS($I$38:$I$182,$C$38:$C$182,C10)=0,"",SUMIFS($I$38:$I$182,$C$38:$C$182,C10)) | J10: =IF($H$26>0,H10/$H$26,0) -> 0.045288631
B11: =INDEX(PARÁMETROS!$F$70:$F$89,MATCH(C11,PARÁMETROS!$A$70:$A$89,0)) -> Acero | C11: Varilla Ø1/4" x 9 m | D11: =INDEX(PARÁMETROS!$B$70:$B$89,MATCH(C11,PARÁMETROS!$A$70:$A$89,0)) -> und | E11: =SUMIFS($E$38:$E$182,$C$38:$C$182,C11) -> 440 | F11: =SUMIFS($F$38:$F$182,$C$38:$C$182,C11) -> 440 | G11: =INDEX(PARÁMETROS!$C$70:$C$89,MATCH(C11,PARÁMETROS!$A$70:$A$89,0)) -> 9.5 | H11: =SUMIFS($H$38:$H$182,$C$38:$C$182,C11) -> 4180 | I11: =IF(SUMIFS($I$38:$I$182,$C$38:$C$182,C11)=0,"",SUMIFS($I$38:$I$182,$C$38:$C$182,C11)) -> 990 | J11: =IF($H$26>0,H11/$H$26,0) -> 0.024458201
B12: =INDEX(PARÁMETROS!$F$70:$F$89,MATCH(C12,PARÁMETROS!$A$70:$A$89,0)) -> Acero | C12: Varilla Ø3/8" x 9 m | D12: =INDEX(PARÁMETROS!$B$70:$B$89,MATCH(C12,PARÁMETROS!$A$70:$A$89,0)) -> und | E12: =SUMIFS($E$38:$E$182,$C$38:$C$182,C12) -> 1152 | F12: =SUMIFS($F$38:$F$182,$C$38:$C$182,C12) -> 1152 | G12: =INDEX(PARÁMETROS!$C$70:$C$89,MATCH(C12,PARÁMETROS!$A$70:$A$89,0)) -> 20.13 | H12: =SUMIFS($H$38:$H$182,$C$38:$C$182,C12) -> 23189.76 | I12: =IF(SUMIFS($I$38:$I$182,$C$38:$C$182,C12)=0,"",SUMIFS($I$38:$I$182,$C$38:$C$182,C12)) -> 5806.08 | J12: =IF($H$26>0,H12/$H$26,0) -> 0.13568895
B13: =INDEX(PARÁMETROS!$F$70:$F$89,MATCH(C13,PARÁMETROS!$A$70:$A$89,0)) -> Acero | C13: Varilla Ø1/2" x 9 m | D13: =INDEX(PARÁMETROS!$B$70:$B$89,MATCH(C13,PARÁMETROS!$A$70:$A$89,0)) -> und | E13: =SUMIFS($E$38:$E$182,$C$38:$C$182,C13) -> 171 | F13: =SUMIFS($F$38:$F$182,$C$38:$C$182,C13) -> 171 | G13: =INDEX(PARÁMETROS!$C$70:$C$89,MATCH(C13,PARÁMETROS!$A$70:$A$89,0)) -> 36.09 | H13: =SUMIFS($H$38:$H$182,$C$38:$C$182,C13) -> 6171.39 | I13: =IF(SUMIFS($I$38:$I$182,$C$38:$C$182,C13)=0,"",SUMIFS($I$38:$I$182,$C$38:$C$182,C13)) -> 1529.766 | J13: =IF($H$26>0,H13/$H$26,0) -> 0.03611031
